Workbook

Sheet TB-Jan
A1: Republic of the Philippines
A2: PROVINCE OF AGUSAN DEL SUR
A3: Gov. Democrito O. Plaza Government Center, Prosperidad
A5: TRUST FUND
A6: TRIAL BALANCE
A7: As of January 31, 2011
E9: =A7 -> As of January 31, 2011 | G9: Check Disbursement | I9: Cash Disbursement | K9: Cash Receipts | M9: General Journal
A11: Account Title | B11: Account Code | C11: Debit | D11: Credit | E11: Debit | F11: Credit | G11: Debit | H11: Credit | I11: Debit | J11: Credit | K11: Debit | L11: Credit | M11: Debit | N11: Credit
A13: Cash in Vault | B13: 101 | C13: =E13-F13 -> 0 | E13: =SUM(G13,I13,K13,M13) -> 0 | F13: =SUM(H13,J13,L13,N13) -> 0
A14: Cash - Collecting Officers | B14: 102 | C14: =E14-F14 -> 0 | E14: =SUM(G14,I14,K14,M14) -> 0 | F14: =SUM(H14,J14,L14,N14) -> 0
A15: Cash Disbursing Officers | B15: 103 | C15: =E15-F15 -> 0 | E15: =SUM(G15,I15,K15,M15) -> 0 | F15: =SUM(H15,J15,L15,N15) -> 0
A16: Petty Cash Fund | B16: 104 | C16: =E16-F16 -> 0 | E16: =SUM(G16,I16,K16,M16) -> 0 | F16: =SUM(H16,J16,L16,N16) -> 0
A17: Payroll Fund | B17: 106 | C17: =E17-F17 -> 0 | E17: =SUM(G17,I17,K17,M17) -> 0 | F17: =SUM(H17,J17,L17,N17) -> 0
A18: Cash - Bangko Sentral ng Pilipinas | B18: 110 | C18: =E18-F18 -> 0 | E18: =SUM(G18,I18,K18,M18) -> 0 | F18: =SUM(H18,J18,L18,N18) -> 0
A19: Cash in Bank - Local Currency, Current Account | B19: 111 | C19: =E19-F19 -> 0 | E19: =SUM(G19,I19,K19,M19) -> 0 | F19: =SUM(H19,J19,L19,N19) -> 0
A20: Cash in Bank - Local Currency, SavingsAccount | B20: 112 | C20: =E20-F20 -> 0 | E20: =SUM(G20,I20,K20,M20) -> 0 | F20: =SUM(H20,J20,L20,N20) -> 0
A21: Cash in Bank - Local Currency, Time Deposits | B21: 113 | C21: =E21-F21 -> 0 | E21: =SUM(G21,I21,K21,M21) -> 0 | F21: =SUM(H21,J21,L21,N21) -> 0
A22: Cash - Bangko Sentral ng Pilipinas | B22: 114 | C22: =E22-F22 -> 0 | E22: =SUM(G22,I22,K22,M22) -> 0 | F22: =SUM(H22,J22,L22,N22) -> 0
A23: Cash in Bank - Foreign Currency, Current Account | B23: 115 | C23: =E23-F23 -> 0 | E23: =SUM(G23,I23,K23,M23) -> 0 | F23: =SUM(H23,J23,L23,N23) -> 0
A24: Cash in Bank - Foreign Currency, Savings Account | B24: 116 | C24: =E24-F24 -> 0 | E24: =SUM(G24,I24,K24,M24) -> 0 | F24: =SUM(H24,J24,L24,N24) -> 0
A25: Cash in Bank - Foreign Currency, Time Deposits | B25: 117 | C25: =E25-F25 -> 0 | E25: =SUM(G25,I25,K25,M25) -> 0 | F25: =SUM(H25,J25,L25,N25) -> 0
A26: Accounts Receivable | B26: 121 | C26: =E26-F26 -> 0 | E26: =SUM(G26,I26,K26,M26) -> 0 | F26: =SUM(H26,J26,L26,N26) -> 0
A27: Allowance for Doubtful Accounts | B27: 301 | C27: =E27-F27 -> 0 | E27: =SUM(G27,I27,K27,M27) -> 0 | F27: =SUM(H27,J27,L27,N27) -> 0
A28: Notes Receivable | B28: 122 | C28: =E28-F28 -> 0 | E28: =SUM(G28,I28,K28,M28) -> 0 | F28: =SUM(H28,J28,L28,N28) -> 0
A29: Due from Officers and Employees | B29: 123 | C29: =E29-F29 -> 0 | E29: =SUM(G29,I29,K29,M29) -> 0 | F29: =SUM(H29,J29,L29,N29) -> 0
A30: Loans Receivable - GOCCs | B30: 124 | C30: =E30-F30 -> 0 | E30: =SUM(G30,I30,K30,M30) -> 0 | F30: =SUM(H30,J30,L30,N30) -> 0
A31: Loans Receivable - LGUs | B31: 125 | C31: =E31-F31 -> 0 | E31: =SUM(G31,I31,K31,M31) -> 0 | F31: =SUM(H31,J31,L31,N31) -> 0
A32: Loans Receivable - Others | B32: 126 | C32: =E32-F32 -> 0 | E32: =SUM(G32,I32,K32,M32) -> 0 | F32: =SUM(H32,J32,L32,N32) -> 0
A33: Real Property Tax Receivable | B33: 127 | C33: =E33-F33 -> 0 | E33: =SUM(G33,I33,K33,M33) -> 0 | F33: =SUM(H33,J33,L33,N33) -> 0
A34: Special Education Tax Receivable | B34: 128 | C34: =E34-F34 -> 0 | E34: =SUM(G34,I34,K34,M34) -> 0 | F34: =SUM(H34,J34,L34,N34) -> 0
A35: Interests Receivable | B35: 129 | C35: =E35-F35 -> 0 | E35: =SUM(G35,I35,K35,M35) -> 0 | F35: =SUM(H35,J35,L35,N35) -> 0
... A37: Due from GOCCs | B37: 137 | C37: =E37-F37 -> 0 | E37: =SUM(G37,I37,K37,M37) -> 0 | F37: =SUM(H37,J37,L37,N37) -> 0
A38: Due from LGUs | B38: 138 | C38: =E38-F38 -> 0 | E38: =SUM(G38,I38,K38,M38) -> 0 | F38: =SUM(H38,J38,L38,N38) -> 0
A39: Due from NGOs/POs | B39: 139 | C39: =E39-F39 -> 0 | E39: =SUM(G39,I39,K39,M39) -> 0 | F39: =SUM(H39,J39,L39,N39) -> 0
A40: Due from Other Funds | B40: 144 | C40: =E40-F40 -> 0 | E40: =SUM(G40,I40,K40,M40) -> 0 | F40: =SUM(H40,J40,L40,N40) -> 0
A41: Receivables - Disallowances/Charges | B41: 146 | C41: =E41-F41 -> 0 | E41: =SUM(G41,I41,K41,M41) -> 0 | F41: =SUM(H41,J41,L41,N41) -> 0
A42: Advances to Officers and Employees | B42: 148 | C42: =E42-F42 -> 0 | E42: =SUM(G42,I42,K42,M42) -> 0 | F42: =SUM(H42,J42,L42,N42) -> 0
A43: Other Receivables | B43: 149 | C43: =E43-F43 -> 0 | E43: =SUM(G43,I43,K43,M43) -> 0 | F43: =SUM(H43,J43,L43,N43) -> 0
A44: Raw Materials Inventory | B44: 151 | C44: =E44-F44 -> 0 | E44: =SUM(G44,I44,K44,M44) -> 0 | F44: =SUM(H44,J44,L44,N44) -> 0
A45: Work-In-Process Inventory | B45: 152 | C45: =E45-F45 -> 0 | E45: =SUM(G45,I45,K45,M45) -> 0 | F45: =SUM(H45,J45,L45,N45) -> 0
...

Sheet TB-Feb
A1: Republic of the Philippines
A2: PROVINCE OF AGUSAN DEL SUR
A3: Gov. Democrito O. Plaza Government Center, Prosperidad
A5: TRUST FUND
A6: TRIAL BALANCE
A7: As of February 28, 2011
E9: =A7 -> As of February 28, 2011 | G9: Check Disbursement | I9: Cash Disbursement | K9: Cash Receipts | M9: General Journal
A11: Account Title | B11: Account Code | C11: Debit | D11: Credit | E11: Debit | F11: Credit | G11: Debit | H11: Credit | I11: Debit | J11: Credit | K11: Debit | L11: Credit | M11: Debit | N11: Credit
A13: Cash in Vault | B13: 101 | C13: =E13-F13 -> 0 | E13: =SUM(G13,I13,K13,M13) -> 0 | F13: =SUM(H13,J13,L13,N13) -> 0
A14: Cash - Collecting Officers | B14: 102 | C14: =E14-F14 -> 0 | E14: =SUM(G14,I14,K14,M14) -> 0 | F14: =SUM(H14,J14,L14,N14) -> 0
A15: Cash Disbursing Officers | B15: 103 | C15: =E15-F15 -> 0 | E15: =SUM(G15,I15,K15,M15) -> 0 | F15: =SUM(H15,J15,L15,N15) -> 0
A16: Petty Cash Fund | B16: 104 | C16: =E16-F16 -> 0 | E16: =SUM(G16,I16,K16,M16) -> 0 | F16: =SUM(H16,J16,L16,N16) -> 0
A17: Payroll Fund | B17: 106 | C17: =E17-F17 -> 0 | E17: =SUM(G17,I17,K17,M17) -> 0 | F17: =SUM(H17,J17,L17,N17) -> 0
A18: Cash - Bangko Sentral ng Pilipinas | B18: 110 | C18: =E18-F18 -> 0 | E18: =SUM(G18,I18,K18,M18) -> 0 | F18: =SUM(H18,J18,L18,N18) -> 0
A19: Cash in Bank - Local Currency, Current Account | B19: 111 | C19: =E19-F19 -> 0 | E19: =SUM(G19,I19,K19,M19) -> 0 | F19: =SUM(H19,J19,L19,N19) -> 0
A20: Cash in Bank - Local Currency, SavingsAccount | B20: 112 | C20: =E20-F20 -> 0 | E20: =SUM(G20,I20,K20,M20) -> 0 | F20: =SUM(H20,J20,L20,N20) -> 0
A21: Cash in Bank - Local Currency, Time Deposits | B21: 113 | C21: =E21-F21 -> 0 | E21: =SUM(G21,I21,K21,M21) -> 0 | F21: =SUM(H21,J21,L21,N21) -> 0
A22: Cash - Bangko Sentral ng Pilipinas | B22: 114 | C22: =E22-F22 -> 0 | E22: =SUM(G22,I22,K22,M22) -> 0 | F22: =SUM(H22,J22,L22,N22) -> 0
A23: Cash in Bank - Foreign Currency, Current Account | B23: 115 | C23: =E23-F23 -> 0 | E23: =SUM(G23,I23,K23,M23) -> 0 | F23: =SUM(H23,J23,L23,N23) -> 0
A24: Cash in Bank - Foreign Currency, Savings Account | B24: 116 | C24: =E24-F24 -> 0 | E24: =SUM(G24,I24,K24,M24) -> 0 | F24: =SUM(H24,J24,L24,N24) -> 0
A25: Cash in Bank - Foreign Currency, Time Deposits | B25: 117 | C25: =E25-F25 -> 0 | E25: =SUM(G25,I25,K25,M25) -> 0 | F25: =SUM(H25,J25,L25,N25) -> 0
A26: Accounts Receivable | B26: 121 | C26: =E26-F26 -> 0 | E26: =SUM(G26,I26,K26,M26) -> 0 | F26: =SUM(H26,J26,L26,N26) -> 0
A27: Allowance for Doubtful Accounts | B27: 301 | C27: =E27-F27 -> 0 | E27: =SUM(G27,I27,K27,M27) -> 0 | F27: =SUM(H27,J27,L27,N27) -> 0
A28: Notes Receivable | B28: 122 | C28: =E28-F28 -> 0 | E28: =SUM(G28,I28,K28,M28) -> 0 | F28: =SUM(H28,J28,L28,N28) -> 0
A29: Due from Officers and Employees | B29: 123 | C29: =E29-F29 -> 0 | E29: =SUM(G29,I29,K29,M29) -> 0 | F29: =SUM(H29,J29,L29,N29) -> 0
A30: Loans Receivable - GOCCs | B30: 124 | C30: =E30-F30 -> 0 | E30: =SUM(G30,I30,K30,M30) -> 0 | F30: =SUM(H30,J30,L30,N30) -> 0
A31: Loans Receivable - LGUs | B31: 125 | C31: =E31-F31 -> 0 | E31: =SUM(G31,I31,K31,M31) -> 0 | F31: =SUM(H31,J31,L31,N31) -> 0
A32: Loans Receivable - Others | B32: 126 | C32: =E32-F32 -> 0 | E32: =SUM(G32,I32,K32,M32) -> 0 | F32: =SUM(H32,J32,L32,N32) -> 0
A33: Real Property Tax Receivable | B33: 127 | C33: =E33-F33 -> 0 | E33: =SUM(G33,I33,K33,M33) -> 0 | F33: =SUM(H33,J33,L33,N33) -> 0
A34: Special Education Tax Receivable | B34: 128 | C34: =E34-F34 -> 0 | E34: =SUM(G34,I34,K34,M34) -> 0 | F34: =SUM(H34,J34,L34,N34) -> 0
A35: Interests Receivable | B35: 129 | C35: =E35-F35 -> 0 | E35: =SUM(G35,I35,K35,M35) -> 0 | F35: =SUM(H35,J35,L35,N35) -> 0
... A37: Due from GOCCs | B37: 137 | C37: =E37-F37 -> 0 | E37: =SUM(G37,I37,K37,M37) -> 0 | F37: =SUM(H37,J37,L37,N37) -> 0
A38: Due from LGUs | B38: 138 | C38: =E38-F38 -> 0 | E38: =SUM(G38,I38,K38,M38) -> 0 | F38: =SUM(H38,J38,L38,N38) -> 0
A39: Due from NGOs/POs | B39: 139 | C39: =E39-F39 -> 0 | E39: =SUM(G39,I39,K39,M39) -> 0 | F39: =SUM(H39,J39,L39,N39) -> 0
A40: Due from Other Funds | B40: 144 | C40: =E40-F40 -> 0 | E40: =SUM(G40,I40,K40,M40) -> 0 | F40: =SUM(H40,J40,L40,N40) -> 0
A41: Receivables - Disallowances/Charges | B41: 146 | C41: =E41-F41 -> 0 | E41: =SUM(G41,I41,K41,M41) -> 0 | F41: =SUM(H41,J41,L41,N41) -> 0
A42: Advances to Officers and Employees | B42: 148 | C42: =E42-F42 -> 0 | E42: =SUM(G42,I42,K42,M42) -> 0 | F42: =SUM(H42,J42,L42,N42) -> 0
A43: Other Receivables | B43: 149 | C43: =E43-F43 -> 0 | E43: =SUM(G43,I43,K43,M43) -> 0 | F43: =SUM(H43,J43,L43,N43) -> 0
A44: Raw Materials Inventory | B44: 151 | C44: =E44-F44 -> 0 | E44: =SUM(G44,I44,K44,M44) -> 0 | F44: =SUM(H44,J44,L44,N44) -> 0
A45: Work-In-Process Inventory | B45: 152 | C45: =E45-F45 -> 0 | E45: =SUM(G45,I45,K45,M45) -> 0 | F45: =SUM(H45,J45,L45,N45) -> 0
...

Sheet TB-Mar
A1: Republic of the Philippines
A2: PROVINCE OF AGUSAN DEL SUR
A3: Gov. Democrito O. Plaza Government Center, Prosperidad
A5: TRUST FUND
A6: TRIAL BALANCE
A7: As of March 31, 2011
E9: =A7 -> As of March 31, 2011 | G9: Check Disbursement | I9: Cash Disbursement | K9: Cash Receipts | M9: General Journal
A11: Account Title | B11: Account Code | C11: Debit | D11: Credit | E11: Debit | F11: Credit | G11: Debit | H11: Credit | I11: Debit | J11: Credit | K11: Debit | L11: Credit | M11: Debit | N11: Credit
A13: Cash in Vault | B13: 101 | C13: =E13-F13 -> 0 | E13: =SUM(G13,I13,K13,M13) -> 0 | F13: =SUM(H13,J13,L13,N13) -> 0
A14: Cash - Collecting Officers | B14: 102 | C14: =E14-F14 -> 0 | E14: =SUM(G14,I14,K14,M14) -> 0 | F14: =SUM(H14,J14,L14,N14) -> 0
A15: Cash Disbursing Officers | B15: 103 | C15: =E15-F15 -> 0 | E15: =SUM(G15,I15,K15,M15) -> 0 | F15: =SUM(H15,J15,L15,N15) -> 0
A16: Petty Cash Fund | B16: 104 | C16: =E16-F16 -> 0 | E16: =SUM(G16,I16,K16,M16) -> 0 | F16: =SUM(H16,J16,L16,N16) -> 0
A17: Payroll Fund | B17: 106 | C17: =E17-F17 -> 0 | E17: =SUM(G17,I17,K17,M17) -> 0 | F17: =SUM(H17,J17,L17,N17) -> 0
A18: Cash - Bangko Sentral ng Pilipinas | B18: 110 | C18: =E18-F18 -> 0 | E18: =SUM(G18,I18,K18,M18) -> 0 | F18: =SUM(H18,J18,L18,N18) -> 0
A19: Cash in Bank - Local Currency, Current Account | B19: 111 | C19: =E19-F19 -> 0 | E19: =SUM(G19,I19,K19,M19) -> 0 | F19: =SUM(H19,J19,L19,N19) -> 0
A20: Cash in Bank - Local Currency, SavingsAccount | B20: 112 | C20: =E20-F20 -> 0 | E20: =SUM(G20,I20,K20,M20) -> 0 | F20: =SUM(H20,J20,L20,N20) -> 0
A21: Cash in Bank - Local Currency, Time Deposits | B21: 113 | C21: =E21-F21 -> 0 | E21: =SUM(G21,I21,K21,M21) -> 0 | F21: =SUM(H21,J21,L21,N21) -> 0
A22: Cash - Bangko Sentral ng Pilipinas | B22: 114 | C22: =E22-F22 -> 0 | E22: =SUM(G22,I22,K22,M22) -> 0 | F22: =SUM(H22,J22,L22,N22) -> 0
A23: Cash in Bank - Foreign Currency, Current Account | B23: 115 | C23: =E23-F23 -> 0 | E23: =SUM(G23,I23,K23,M23) -> 0 | F23: =SUM(H23,J23,L23,N23) -> 0
A24: Cash in Bank - Foreign Currency, Savings Account | B24: 116 | C24: =E24-F24 -> 0 | E24: =SUM(G24,I24,K24,M24) -> 0 | F24: =SUM(H24,J24,L24,N24) -> 0
A25: Cash in Bank - Foreign Currency, Time Deposits | B25: 117 | C25: =E25-F25 -> 0 | E25: =SUM(G25,I25,K25,M25) -> 0 | F25: =SUM(H25,J25,L25,N25) -> 0
A26: Accounts Receivable | B26: 121 | C26: =E26-F26 -> 0 | E26: =SUM(G26,I26,K26,M26) -> 0 | F26: =SUM(H26,J26,L26,N26) -> 0
A27: Allowance for Doubtful Accounts | B27: 301 | C27: =E27-F27 -> 0 | E27: =SUM(G27,I27,K27,M27) -> 0 | F27: =SUM(H27,J27,L27,N27) -> 0
A28: Notes Receivable | B28: 122 | C28: =E28-F28 -> 0 | E28: =SUM(G28,I28,K28,M28) -> 0 | F28: =SUM(H28,J28,L28,N28) -> 0
A29: Due from Officers and Employees | B29: 123 | C29: =E29-F29 -> 0 | E29: =SUM(G29,I29,K29,M29) -> 0 | F29: =SUM(H29,J29,L29,N29) -> 0
A30: Loans Receivable - GOCCs | B30: 124 | C30: =E30-F30 -> 0 | E30: =SUM(G30,I30,K30,M30) -> 0 | F30: =SUM(H30,J30,L30,N30) -> 0
A31: Loans Receivable - LGUs | B31: 125 | C31: =E31-F31 -> 0 | E31: =SUM(G31,I31,K31,M31) -> 0 | F31: =SUM(H31,J31,L31,N31) -> 0
A32: Loans Receivable - Others | B32: 126 | C32: =E32-F32 -> 0 | E32: =SUM(G32,I32,K32,M32) -> 0 | F32: =SUM(H32,J32,L32,N32) -> 0
A33: Real Property Tax Receivable | B33: 127 | C33: =E33-F33 -> 0 | E33: =SUM(G33,I33,K33,M33) -> 0 | F33: =SUM(H33,J33,L33,N33) -> 0
A34: Special Education Tax Receivable | B34: 128 | C34: =E34-F34 -> 0 | E34: =SUM(G34,I34,K34,M34) -> 0 | F34: =SUM(H34,J34,L34,N34) -> 0
A35: Interests Receivable | B35: 129 | C35: =E35-F35 -> 0 | E35: =SUM(G35,I35,K35,M35) -> 0 | F35: =SUM(H35,J35,L35,N35) -> 0
... A37: Due from GOCCs | B37: 137 | C37: =E37-F37 -> 0 | E37: =SUM(G37,I37,K37,M37) -> 0 | F37: =SUM(H37,J37,L37,N37) -> 0
A38: Due from LGUs | B38: 138 | C38: =E38-F38 -> 0 | E38: =SUM(G38,I38,K38,M38) -> 0 | F38: =SUM(H38,J38,L38,N38) -> 0
A39: Due from NGOs/POs | B39: 139 | C39: =E39-F39 -> 0 | E39: =SUM(G39,I39,K39,M39) -> 0 | F39: =SUM(H39,J39,L39,N39) -> 0
A40: Due from Other Funds | B40: 144 | C40: =E40-F40 -> 0 | E40: =SUM(G40,I40,K40,M40) -> 0 | F40: =SUM(H40,J40,L40,N40) -> 0
A41: Receivables - Disallowances/Charges | B41: 146 | C41: =E41-F41 -> 0 | E41: =SUM(G41,I41,K41,M41) -> 0 | F41: =SUM(H41,J41,L41,N41) -> 0
A42: Advances to Officers and Employees | B42: 148 | C42: =E42-F42 -> 0 | E42: =SUM(G42,I42,K42,M42) -> 0 | F42: =SUM(H42,J42,L42,N42) -> 0
A43: Other Receivables | B43: 149 | C43: =E43-F43 -> 0 | E43: =SUM(G43,I43,K43,M43) -> 0 | F43: =SUM(H43,J43,L43,N43) -> 0
A44: Raw Materials Inventory | B44: 151 | C44: =E44-F44 -> 0 | E44: =SUM(G44,I44,K44,M44) -> 0 | F44: =SUM(H44,J44,L44,N44) -> 0
A45: Work-In-Process Inventory | B45: 152 | C45: =E45-F45 -> 0 | E45: =SUM(G45,I45,K45,M45) -> 0 | F45: =SUM(H45,J45,L45,N45) -> 0
...

Sheet TB-Apr
A1: Republic of the Philippines
A2: PROVINCE OF AGUSAN DEL SUR
A3: Gov. Democrito O. Plaza Government Center, Prosperidad
A5: TRUST FUND
A6: TRIAL BALANCE
A7: As of April 30, 2011
E9: =A7 -> As of April 30, 2011 | G9: TB for April | I9: Cash Disbursement | K9: Cash Receipts | M9: General Journal
A11: Account Title | B11: Account Code | C11: Debit | D11: Credit | E11: Debit | F11: Credit | G11: Debit | H11: Credit | I11: Debit | J11: Credit | K11: Debit | L11: Credit | M11: Debit | N11: Credit
A13: Cash in Vault | B13: 101 | C13: =E13-F13 -> 0 | E13: =SUM(G13,I13,K13,M13) -> 0 | F13: =SUM(H13,J13,L13,N13) -> 0
A14: Cash - Collecting Officers | B14: 102 | C14: =E14-F14 -> 0 | E14: =SUM(G14,I14,K14,M14) -> 0 | F14: =SUM(H14,J14,L14,N14) -> 0
A15: Cash Disbursing Officers | B15: 103 | C15: =E15-F15 -> 0 | E15: =SUM(G15,I15,K15,M15) -> 0 | F15: =SUM(H15,J15,L15,N15) -> 0
A16: Petty Cash Fund | B16: 104 | C16: =E16-F16 -> 50000 | E16: =SUM(G16,I16,K16,M16) -> 50000 | F16: =SUM(H16,J16,L16,N16) -> 0 | G16: 50000
A17: Payroll Fund | B17: 106 | C17: =E17-F17 -> 4876.62 | E17: =SUM(G17,I17,K17,M17) -> 4876.62 | F17: =SUM(H17,J17,L17,N17) -> 0 | G17: 4876.62
A18: Cash - Bangko Sentral ng Pilipinas | B18: 110 | C18: =E18-F18 -> 0 | E18: =SUM(G18,I18,K18,M18) -> 0 | F18: =SUM(H18,J18,L18,N18) -> 0
A19: Cash in Bank - Local Currency, Current Account | B19: 111 | C19: =E19-F19 -> 75809618 | E19: =SUM(G19,I19,K19,M19) -> 75809618 | F19: =SUM(H19,J19,L19,N19) -> 0 | G19: 75809618
A20: Cash in Bank - Local Currency, SavingsAccount | B20: 112 | C20: =E20-F20 -> 4335118.1 | E20: =SUM(G20,I20,K20,M20) -> 4335118.1 | F20: =SUM(H20,J20,L20,N20) -> 0 | G20: 4335118.1
A21: Cash in Bank - Local Currency, Time Deposits | B21: 113 | C21: =E21-F21 -> 0 | E21: =SUM(G21,I21,K21,M21) -> 0 | F21: =SUM(H21,J21,L21,N21) -> 0
A22: Cash - Bangko Sentral ng Pilipinas | B22: 114 | C22: =E22-F22 -> 0 | E22: =SUM(G22,I22,K22,M22) -> 0 | F22: =SUM(H22,J22,L22,N22) -> 0
A23: Cash in Bank - Foreign Currency, Current Account | B23: 115 | C23: =E23-F23 -> 0 | E23: =SUM(G23,I23,K23,M23) -> 0 | F23: =SUM(H23,J23,L23,N23) -> 0
A24: Cash in Bank - Foreign Currency, Savings Account | B24: 116 | C24: =E24-F24 -> 0 | E24: =SUM(G24,I24,K24,M24) -> 0 | F24: =SUM(H24,J24,L24,N24) -> 0
A25: Cash in Bank - Foreign Currency, Time Deposits | B25: 117 | C25: =E25-F25 -> 0 | E25: =SUM(G25,I25,K25,M25) -> 0 | F25: =SUM(H25,J25,L25,N25) -> 0
A26: Accounts Receivable | B26: 121 | C26: =E26-F26 -> 0 | E26: =SUM(G26,I26,K26,M26) -> 0 | F26: =SUM(H26,J26,L26,N26) -> 0
A27: Allowance for Doubtful Accounts | B27: 301 | C27: =E27-F27 -> 0 | E27: =SUM(G27,I27,K27,M27) -> 0 | F27: =SUM(H27,J27,L27,N27) -> 0
A28: Notes Receivable | B28: 122 | C28: =E28-F28 -> 0 | E28: =SUM(G28,I28,K28,M28) -> 0 | F28: =SUM(H28,J28,L28,N28) -> 0
A29: Due from Officers and Employees | B29: 123 | C29: =E29-F29 -> 0 | E29: =SUM(G29,I29,K29,M29) -> 0 | F29: =SUM(H29,J29,L29,N29) -> 0
A30: Loans Receivable - GOCCs | B30: 124 | C30: =E30-F30 -> 0 | E30: =SUM(G30,I30,K30,M30) -> 0 | F30: =SUM(H30,J30,L30,N30) -> 0
A31: Loans Receivable - LGUs | B31: 125 | C31: =E31-F31 -> 0 | E31: =SUM(G31,I31,K31,M31) -> 0 | F31: =SUM(H31,J31,L31,N31) -> 0
A32: Loans Receivable - Others | B32: 126 | C32: =E32-F32 -> 0 | E32: =SUM(G32,I32,K32,M32) -> 0 | F32: =SUM(H32,J32,L32,N32) -> 0
A33: Real Property Tax Receivable | B33: 127 | C33: =E33-F33 -> 0 | E33: =SUM(G33,I33,K33,M33) -> 0 | F33: =SUM(H33,J33,L33,N33) -> 0
A34: Special Education Tax Receivable | B34: 128 | C34: =E34-F34 -> 0 | E34: =SUM(G34,I34,K34,M34) -> 0 | F34: =SUM(H34,J34,L34,N34) -> 0
A35: Interests Receivable | B35: 129 | C35: =E35-F35 -> 0 | E35: =SUM(G35,I35,K35,M35) -> 0 | F35: =SUM(H35,J35,L35,N35) -> 0
... A37: Due from GOCCs | B37: 137 | C37: =E37-F37 -> 0 | E37: =SUM(G37,I37,K37,M37) -> 0 | F37: =SUM(H37,J37,L37,N37) -> 0
A38: Due from LGUs | B38: 138 | C38: =E38-F38 -> 1183464.4 | E38: =SUM(G38,I38,K38,M38) -> 1183464.4 | F38: =SUM(H38,J38,L38,N38) -> 0 | G38: 1183464.4
A39: Due from NGOs/POs | B39: 139 | C39: =E39-F39 -> 1897625 | E39: =SUM(G39,I39,K39,M39) -> 1897625 | F39: =SUM(H39,J39,L39,N39) -> 0 | G39: 1897625
A40: Due from Other Funds | B40: 144 | C40: =E40-F40 -> 0 | E40: =SUM(G40,I40,K40,M40) -> 0 | F40: =SUM(H40,J40,L40,N40) -> 0
A41: Receivables - Disallowances/Charges | B41: 146 | C41: =E41-F41 -> 0 | E41: =SUM(G41,I41,K41,M41) -> 0 | F41: =SUM(H41,J41,L41,N41) -> 0
A42: Advances to Officers and Employees | B42: 148 | C42: =E42-F42 -> 29984964 | E42: =SUM(G42,I42,K42,M42) -> 29984964 | F42: =SUM(H42,J42,L42,N42) -> 0 | G42: 29984964
A43: Other Receivables | B43: 149 | C43: =E43-F43 -> 312433.89 | E43: =SUM(G43,I43,K43,M43) -> 312433.89 | F43: =SUM(H43,J43,L43,N43) -> 0 | G43: 312433.89
A44: Raw Materials Inventory | B44: 151 | C44: =E44-F44 -> 0 | E44: =SUM(G44,I44,K44,M44) -> 0 | F44: =SUM(H44,J44,L44,N44) -> 0
A45: Work-In-Process Inventory | B45: 152 | C45: =E45-F45 -> 0 | E45: =SUM(G45,I45,K45,M45) -> 0 | F45: =SUM(H45,J45,L45,N45) -> 0
...

Sheet TB-May
A1: Republic of the Philippines
A2: PROVINCE OF AGUSAN DEL SUR
A3: Gov. Democrito O. Plaza Government Center, Prosperidad
A5: TRUST FUND
A6: TRIAL BALANCE
A7: As of May 31, 2011
E9: =A7 -> As of May 31, 2011 | G9: Check Disbursement | I9: Cash Disbursement | K9: Cash Receipts | M9: General Journal
A11: Account Title | B11: Account Code | C11: Debit | D11: Credit | E11: Debit | F11: Credit | G11: Debit | H11: Credit | I11: Debit | J11: Credit | K11: Debit | L11: Credit | M11: Debit | N11: Credit
A13: Cash in Vault | B13: 101 | C13: =E13-F13 -> 0 | E13: =SUM(G13,I13,K13,M13) -> 6835876.3 | F13: =SUM(H13,J13,L13,N13) -> 6835876.3 | K13: 6835876.3 | L13: 6835876.3
A14: Cash - Collecting Officers | B14: 102 | C14: =E14-F14 -> 0 | E14: =SUM(G14,I14,K14,M14) -> 0 | F14: =SUM(H14,J14,L14,N14) -> 0
A15: Cash Disbursing Officers | B15: 103 | C15: =E15-F15 -> 0 | E15: =SUM(G15,I15,K15,M15) -> 0 | F15: =SUM(H15,J15,L15,N15) -> 0
A16: Petty Cash Fund | B16: 104 | C16: =E16-F16 -> 0 | E16: =SUM(G16,I16,K16,M16) -> 0 | F16: =SUM(H16,J16,L16,N16) -> 0
A17: Payroll Fund | B17: 106 | C17: =E17-F17 -> 3055.17 | E17: =SUM(G17,I17,K17,M17) -> 855808.91 | F17: =SUM(H17,J17,L17,N17) -> 852753.74 | G17: 855808.91 | J17: 848948.9 | L17: 3804.84
A18: Cash - Bangko Sentral ng Pilipinas | B18: 110 | C18: =E18-F18 -> 0 | E18: =SUM(G18,I18,K18,M18) -> 0 | F18: =SUM(H18,J18,L18,N18) -> 0
A19: Cash in Bank - Local Currency, Current Account | B19: 111 | C19: =E19-F19 -> 1646765.4 | E19: =SUM(G19,I19,K19,M19) -> 7473654.3 | F19: =SUM(H19,J19,L19,N19) -> 5826888.9 | H19: 5826888.9 | K19: 6835876.3 | M19: 637778
A20: Cash in Bank - Local Currency, SavingsAccount | B20: 112 | C20: =E20-F20 -> 0 | E20: =SUM(G20,I20,K20,M20) -> 0 | F20: =SUM(H20,J20,L20,N20) -> 0
A21: Cash in Bank - Local Currency, Time Deposits | B21: 113 | C21: =E21-F21 -> 0 | E21: =SUM(G21,I21,K21,M21) -> 0 | F21: =SUM(H21,J21,L21,N21) -> 0
A22: Cash - Bangko Sentral ng Pilipinas | B22: 114 | C22: =E22-F22 -> 0 | E22: =SUM(G22,I22,K22,M22) -> 0 | F22: =SUM(H22,J22,L22,N22) -> 0
A23: Cash in Bank - Foreign Currency, Current Account | B23: 115 | C23: =E23-F23 -> 0 | E23: =SUM(G23,I23,K23,M23) -> 0 | F23: =SUM(H23,J23,L23,N23) -> 0
A24: Cash in Bank - Foreign Currency, Savings Account | B24: 116 | C24: =E24-F24 -> 0 | E24: =SUM(G24,I24,K24,M24) -> 0 | F24: =SUM(H24,J24,L24,N24) -> 0
A25: Cash in Bank - Foreign Currency, Time Deposits | B25: 117 | C25: =E25-F25 -> 0 | E25: =SUM(G25,I25,K25,M25) -> 0 | F25: =SUM(H25,J25,L25,N25) -> 0
A26: Accounts Receivable | B26: 121 | C26: =E26-F26 -> 0 | E26: =SUM(G26,I26,K26,M26) -> 0 | F26: =SUM(H26,J26,L26,N26) -> 0
A27: Allowance for Doubtful Accounts | B27: 301 | C27: =E27-F27 -> 0 | E27: =SUM(G27,I27,K27,M27) -> 0 | F27: =SUM(H27,J27,L27,N27) -> 0
A28: Notes Receivable | B28: 122 | C28: =E28-F28 -> 0 | E28: =SUM(G28,I28,K28,M28) -> 0 | F28: =SUM(H28,J28,L28,N28) -> 0
A29: Due from Officers and Employees | B29: 123 | C29: =E29-F29 -> 0 | E29: =SUM(G29,I29,K29,M29) -> 0 | F29: =SUM(H29,J29,L29,N29) -> 0
A30: Loans Receivable - GOCCs | B30: 124 | C30: =E30-F30 -> 0 | E30: =SUM(G30,I30,K30,M30) -> 0 | F30: =SUM(H30,J30,L30,N30) -> 0
A31: Loans Receivable - LGUs | B31: 125 | C31: =E31-F31 -> 0 | E31: =SUM(G31,I31,K31,M31) -> 0 | F31: =SUM(H31,J31,L31,N31) -> 0
A32: Loans Receivable - Others | B32: 126 | C32: =E32-F32 -> 0 | E32: =SUM(G32,I32,K32,M32) -> 0 | F32: =SUM(H32,J32,L32,N32) -> 0
A33: Real Property Tax Receivable | B33: 127 | C33: =E33-F33 -> 0 | E33: =SUM(G33,I33,K33,M33) -> 0 | F33: =SUM(H33,J33,L33,N33) -> 0
A34: Special Education Tax Receivable | B34: 128 | C34: =E34-F34 -> 0 | E34: =SUM(G34,I34,K34,M34) -> 0 | F34: =SUM(H34,J34,L34,N34) -> 0
A35: Interests Receivable | B35: 129 | C35: =E35-F35 -> 0 | E35: =SUM(G35,I35,K35,M35) -> 0 | F35: =SUM(H35,J35,L35,N35) -> 0
... A37: Due from GOCCs | B37: 137 | C37: =E37-F37 -> 0 | E37: =SUM(G37,I37,K37,M37) -> 0 | F37: =SUM(H37,J37,L37,N37) -> 0
A38: Due from LGUs | B38: 138 | C38: =E38-F38 -> 0 | E38: =SUM(G38,I38,K38,M38) -> 0 | F38: =SUM(H38,J38,L38,N38) -> 0
A39: Due from NGOs/POs | B39: 139 | C39: =E39-F39 -> 0 | E39: =SUM(G39,I39,K39,M39) -> 0 | F39: =SUM(H39,J39,L39,N39) -> 0
A40: Due from Other Funds | B40: 144 | C40: =E40-F40 -> 0 | E40: =SUM(G40,I40,K40,M40) -> 0 | F40: =SUM(H40,J40,L40,N40) -> 0
A41: Receivables - Disallowances/Charges | B41: 146 | C41: =E41-F41 -> 0 | E41: =SUM(G41,I41,K41,M41) -> 0 | F41: =SUM(H41,J41,L41,N41) -> 0
A42: Advances to Officers and Employees | B42: 148 | C42: =E42-F42 -> 375223.52 | E42: =SUM(G42,I42,K42,M42) -> 400000 | F42: =SUM(H42,J42,L42,N42) -> 24776.48 | G42: 400000 | L42: 24776.48
A43: Other Receivables | B43: 149 | C43: =E43-F43 -> 0 | E43: =SUM(G43,I43,K43,M43) -> 0 | F43: =SUM(H43,J43,L43,N43) -> 0
A44: Raw Materials Inventory | B44: 151 | C44: =E44-F44 -> 0 | E44: =SUM(G44,I44,K44,M44) -> 0 | F44: =SUM(H44,J44,L44,N44) -> 0
A45: Work-In-Process Inventory | B45: 152 | C45: =E45-F45 -> 0 | E45: =SUM(G45,I45,K45,M45) -> 0 | F45: =SUM(H45,J45,L45,N45) -> 0
...

Sheet TB-Jun
A1: Republic of the Philippines
A2: PROVINCE OF AGUSAN DEL SUR
A3: Gov. Democrito O. Plaza Government Center, Prosperidad
A5: TRUST FUND
A6: TRIAL BALANCE
A7: As of June 30, 2011
E9: =A7 -> As of June 30, 2011 | G9: Check Disbursement | I9: Cash Disbursement | K9: Cash Receipts | M9: General Journal
A11: Account Title | B11: Account Code | C11: Debit | D11: Credit | E11: Debit | F11: Credit | G11: Debit | H11: Credit | I11: Debit | J11: Credit | K11: Debit | L11: Credit | M11: Debit | N11: Credit
A13: Cash in Vault | B13: 101 | C13: =E13-F13 -> 0 | E13: =SUM(G13,I13,K13,M13) -> 7178151.9 | F13: =SUM(H13,J13,L13,N13) -> 7178151.9 | K13: 7178151.9 | L13: 7178151.9
A14: Cash - Collecting Officers | B14: 102 | C14: =E14-F14 -> 0 | E14: =SUM(G14,I14,K14,M14) -> 0 | F14: =SUM(H14,J14,L14,N14) -> 0
A15: Cash Disbursing Officers | B15: 103 | C15: =E15-F15 -> 0 | E15: =SUM(G15,I15,K15,M15) -> 0 | F15: =SUM(H15,J15,L15,N15) -> 0
A16: Petty Cash Fund | B16: 104 | C16: =E16-F16 -> 0 | E16: =SUM(G16,I16,K16,M16) -> 0 | F16: =SUM(H16,J16,L16,N16) -> 0
A17: Payroll Fund | B17: 106 | C17: =E17-F17 -> 0 | E17: =SUM(G17,I17,K17,M17) -> 729606.4 | F17: =SUM(H17,J17,L17,N17) -> 729606.4 | G17: 729606.4 | J17: 729606.4
A18: Cash - Bangko Sentral ng Pilipinas | B18: 110 | C18: =E18-F18 -> 0 | E18: =SUM(G18,I18,K18,M18) -> 0 | F18: =SUM(H18,J18,L18,N18) -> 0
A19: Cash in Bank - Local Currency, Current Account | B19: 111 | C19: =E19-F19 -> 460357.2 | E19: =SUM(G19,I19,K19,M19) -> 9117059.2 | F19: =SUM(H19,J19,L19,N19) -> 8656702 | H19: 8653202 | K19: 7178151.9 | M19: 1938907.4 | N19: 3500
A20: Cash in Bank - Local Currency, SavingsAccount | B20: 112 | C20: =E20-F20 -> 0 | E20: =SUM(G20,I20,K20,M20) -> 0 | F20: =SUM(H20,J20,L20,N20) -> 0
A21: Cash in Bank - Local Currency, Time Deposits | B21: 113 | C21: =E21-F21 -> 0 | E21: =SUM(G21,I21,K21,M21) -> 0 | F21: =SUM(H21,J21,L21,N21) -> 0
A22: Cash - Bangko Sentral ng Pilipinas | B22: 114 | C22: =E22-F22 -> 0 | E22: =SUM(G22,I22,K22,M22) -> 0 | F22: =SUM(H22,J22,L22,N22) -> 0
A23: Cash in Bank - Foreign Currency, Current Account | B23: 115 | C23: =E23-F23 -> 0 | E23: =SUM(G23,I23,K23,M23) -> 0 | F23: =SUM(H23,J23,L23,N23) -> 0
A24: Cash in Bank - Foreign Currency, Savings Account | B24: 116 | C24: =E24-F24 -> 0 | E24: =SUM(G24,I24,K24,M24) -> 0 | F24: =SUM(H24,J24,L24,N24) -> 0
A25: Cash in Bank - Foreign Currency, Time Deposits | B25: 117 | C25: =E25-F25 -> 0 | E25: =SUM(G25,I25,K25,M25) -> 0 | F25: =SUM(H25,J25,L25,N25) -> 0
A26: Accounts Receivable | B26: 121 | C26: =E26-F26 -> 0 | E26: =SUM(G26,I26,K26,M26) -> 0 | F26: =SUM(H26,J26,L26,N26) -> 0
A27: Allowance for Doubtful Accounts | B27: 301 | C27: =E27-F27 -> 0 | E27: =SUM(G27,I27,K27,M27) -> 0 | F27: =SUM(H27,J27,L27,N27) -> 0
A28: Notes Receivable | B28: 122 | C28: =E28-F28 -> 0 | E28: =SUM(G28,I28,K28,M28) -> 0 | F28: =SUM(H28,J28,L28,N28) -> 0
A29: Due from Officers and Employees | B29: 123 | C29: =E29-F29 -> 0 | E29: =SUM(G29,I29,K29,M29) -> 0 | F29: =SUM(H29,J29,L29,N29) -> 0
A30: Loans Receivable - GOCCs | B30: 124 | C30: =E30-F30 -> 0 | E30: =SUM(G30,I30,K30,M30) -> 0 | F30: =SUM(H30,J30,L30,N30) -> 0
A31: Loans Receivable - LGUs | B31: 125 | C31: =E31-F31 -> 0 | E31: =SUM(G31,I31,K31,M31) -> 0 | F31: =SUM(H31,J31,L31,N31) -> 0
A32: Loans Receivable - Others | B32: 126 | C32: =E32-F32 -> 0 | E32: =SUM(G32,I32,K32,M32) -> 0 | F32: =SUM(H32,J32,L32,N32) -> 0
A33: Real Property Tax Receivable | B33: 127 | C33: =E33-F33 -> 0 | E33: =SUM(G33,I33,K33,M33) -> 0 | F33: =SUM(H33,J33,L33,N33) -> 0
A34: Special Education Tax Receivable | B34: 128 | C34: =E34-F34 -> 0 | E34: =SUM(G34,I34,K34,M34) -> 0 | F34: =SUM(H34,J34,L34,N34) -> 0
A35: Interests Receivable | B35: 129 | C35: =E35-F35 -> 0 | E35: =SUM(G35,I35,K35,M35) -> 0 | F35: =SUM(H35,J35,L35,N35) -> 0
... A37: Due from GOCCs | B37: 137 | C37: =E37-F37 -> 0 | E37: =SUM(G37,I37,K37,M37) -> 0 | F37: =SUM(H37,J37,L37,N37) -> 0
A38: Due from LGUs | B38: 138 | C38: =E38-F38 -> 0 | E38: =SUM(G38,I38,K38,M38) -> 0 | F38: =SUM(H38,J38,L38,N38) -> 0
A39: Due from NGOs/POs | B39: 139 | C39: =E39-F39 -> 0 | E39: =SUM(G39,I39,K39,M39) -> 0 | F39: =SUM(H39,J39,L39,N39) -> 0
A40: Due from Other Funds | B40: 144 | C40: =E40-F40 -> 0 | E40: =SUM(G40,I40,K40,M40) -> 0 | F40: =SUM(H40,J40,L40,N40) -> 0
A41: Receivables - Disallowances/Charges | B41: 146 | C41: =E41-F41 -> 0 | E41: =SUM(G41,I41,K41,M41) -> 0 | F41: =SUM(H41,J41,L41,N41) -> 0
A42: Advances to Officers and Employees | B42: 148 | C42: =E42-F42 -> 28411 | E42: =SUM(G42,I42,K42,M42) -> 194920 | F42: =SUM(H42,J42,L42,N42) -> 166509 | G42: 194920 | L42: 16 | N42: 166493
A43: Other Receivables | B43: 149 | C43: =E43-F43 -> 30000 | E43: =SUM(G43,I43,K43,M43) -> 30000 | F43: =SUM(H43,J43,L43,N43) -> 0 | G43: 30000
A44: Raw Materials Inventory | B44: 151 | C44: =E44-F44 -> 0 | E44: =SUM(G44,I44,K44,M44) -> 0 | F44: =SUM(H44,J44,L44,N44) -> 0
A45: Work-In-Process Inventory | B45: 152 | C45: =E45-F45 -> 0 | E45: =SUM(G45,I45,K45,M45) -> 0 | F45: =SUM(H45,J45,L45,N45) -> 0
...

Sheet TB-Jul
A1: Republic of the Philippines
A2: PROVINCE OF AGUSAN DEL SUR
A3: Gov. Democrito O. Plaza Government Center, Prosperidad
A5: TRUST FUND
A6: TRIAL BALANCE
A7: As of July 31, 2011
E9: =A7 -> As of July 31, 2011 | G9: Check Disbursement | I9: Cash Disbursement | K9: Cash Receipts | M9: General Journal
A11: Account Title | B11: Account Code | C11: Debit | D11: Credit | E11: Debit | F11: Credit | G11: Debit | H11: Credit | I11: Debit | J11: Credit | K11: Debit | L11: Credit | M11: Debit | N11: Credit
A13: Cash in Vault | B13: 101 | C13: =E13-F13 -> 0 | E13: =SUM(G13,I13,K13,M13) -> 5645314.5 | F13: =SUM(H13,J13,L13,N13) -> 5645314.5 | K13: 5645314.5 | L13: 5645314.5
A14: Cash - Collecting Officers | B14: 102 | C14: =E14-F14 -> 0 | E14: =SUM(G14,I14,K14,M14) -> 0 | F14: =SUM(H14,J14,L14,N14) -> 0
A15: Cash Disbursing Officers | B15: 103 | C15: =E15-F15 -> 0 | E15: =SUM(G15,I15,K15,M15) -> 0 | F15: =SUM(H15,J15,L15,N15) -> 0
A16: Petty Cash Fund | B16: 104 | C16: =E16-F16 -> 0 | E16: =SUM(G16,I16,K16,M16) -> 0 | F16: =SUM(H16,J16,L16,N16) -> 0
A17: Payroll Fund | B17: 106 | C17: =E17-F17 -> 843.3 | E17: =SUM(G17,I17,K17,M17) -> 2662222.4 | F17: =SUM(H17,J17,L17,N17) -> 2661379.1 | G17: 2662222.1 | J17: 2661379.1 | M17: 0.3
A18: Cash - Bangko Sentral ng Pilipinas | B18: 110 | C18: =E18-F18 -> 0 | E18: =SUM(G18,I18,K18,M18) -> 0 | F18: =SUM(H18,J18,L18,N18) -> 0
A19: Cash in Bank - Local Currency, Current Account | B19: 111 | C19: =E19-F19 -> -5459228.6 | E19: =SUM(G19,I19,K19,M19) -> 5911904.6 | F19: =SUM(H19,J19,L19,N19) -> 11371133 | H19: 11337173 | K19: 5678280.5 | M19: 233624.15 | N19: 33960.45
A20: Cash in Bank - Local Currency, SavingsAccount | B20: 112 | C20: =E20-F20 -> 0 | E20: =SUM(G20,I20,K20,M20) -> 0 | F20: =SUM(H20,J20,L20,N20) -> 0
A21: Cash in Bank - Local Currency, Time Deposits | B21: 113 | C21: =E21-F21 -> 0 | E21: =SUM(G21,I21,K21,M21) -> 0 | F21: =SUM(H21,J21,L21,N21) -> 0
A22: Cash - Bangko Sentral ng Pilipinas | B22: 114 | C22: =E22-F22 -> 0 | E22: =SUM(G22,I22,K22,M22) -> 0 | F22: =SUM(H22,J22,L22,N22) -> 0
A23: Cash in Bank - Foreign Currency, Current Account | B23: 115 | C23: =E23-F23 -> 0 | E23: =SUM(G23,I23,K23,M23) -> 0 | F23: =SUM(H23,J23,L23,N23) -> 0
A24: Cash in Bank - Foreign Currency, Savings Account | B24: 116 | C24: =E24-F24 -> 0 | E24: =SUM(G24,I24,K24,M24) -> 0 | F24: =SUM(H24,J24,L24,N24) -> 0
A25: Cash in Bank - Foreign Currency, Time Deposits | B25: 117 | C25: =E25-F25 -> 0 | E25: =SUM(G25,I25,K25,M25) -> 0 | F25: =SUM(H25,J25,L25,N25) -> 0
A26: Accounts Receivable | B26: 121 | C26: =E26-F26 -> 0 | E26: =SUM(G26,I26,K26,M26) -> 0 | F26: =SUM(H26,J26,L26,N26) -> 0
A27: Allowance for Doubtful Accounts | B27: 301 | C27: =E27-F27 -> 0 | E27: =SUM(G27,I27,K27,M27) -> 0 | F27: =SUM(H27,J27,L27,N27) -> 0
A28: Notes Receivable | B28: 122 | C28: =E28-F28 -> 0 | E28: =SUM(G28,I28,K28,M28) -> 0 | F28: =SUM(H28,J28,L28,N28) -> 0
A29: Due from Officers and Employees | B29: 123 | C29: =E29-F29 -> 0 | E29: =SUM(G29,I29,K29,M29) -> 0 | F29: =SUM(H29,J29,L29,N29) -> 0
A30: Loans Receivable - GOCCs | B30: 124 | C30: =E30-F30 -> 0 | E30: =SUM(G30,I30,K30,M30) -> 0 | F30: =SUM(H30,J30,L30,N30) -> 0
A31: Loans Receivable - LGUs | B31: 125 | C31: =E31-F31 -> 0 | E31: =SUM(G31,I31,K31,M31) -> 0 | F31: =SUM(H31,J31,L31,N31) -> 0
A32: Loans Receivable - Others | B32: 126 | C32: =E32-F32 -> 0 | E32: =SUM(G32,I32,K32,M32) -> 0 | F32: =SUM(H32,J32,L32,N32) -> 0
A33: Real Property Tax Receivable | B33: 127 | C33: =E33-F33 -> 0 | E33: =SUM(G33,I33,K33,M33) -> 0 | F33: =SUM(H33,J33,L33,N33) -> 0
A34: Special Education Tax Receivable | B34: 128 | C34: =E34-F34 -> 0 | E34: =SUM(G34,I34,K34,M34) -> 0 | F34: =SUM(H34,J34,L34,N34) -> 0
A35: Interests Receivable | B35: 129 | C35: =E35-F35 -> 0 | E35: =SUM(G35,I35,K35,M35) -> 0 | F35: =SUM(H35,J35,L35,N35) -> 0
... A37: Due from GOCCs | B37: 137 | C37: =E37-F37 -> 0 | E37: =SUM(G37,I37,K37,M37) -> 0 | F37: =SUM(H37,J37,L37,N37) -> 0
A38: Due from LGUs | B38: 138 | C38: =E38-F38 -> 0 | E38: =SUM(G38,I38,K38,M38) -> 0 | F38: =SUM(H38,J38,L38,N38) -> 0
A39: Due from NGOs/POs | B39: 139 | C39: =E39-F39 -> 0 | E39: =SUM(G39,I39,K39,M39) -> 0 | F39: =SUM(H39,J39,L39,N39) -> 0
A40: Due from Other Funds | B40: 144 | C40: =E40-F40 -> 0 | E40: =SUM(G40,I40,K40,M40) -> 0 | F40: =SUM(H40,J40,L40,N40) -> 0
A41: Receivables - Disallowances/Charges | B41: 146 | C41: =E41-F41 -> 0 | E41: =SUM(G41,I41,K41,M41) -> 0 | F41: =SUM(H41,J41,L41,N41) -> 0
A42: Advances to Officers and Employees | B42: 148 | C42: =E42-F42 -> 22500 | E42: =SUM(G42,I42,K42,M42) -> 22500 | F42: =SUM(H42,J42,L42,N42) -> 0 | G42: 22500
A43: Other Receivables | B43: 149 | C43: =E43-F43 -> 0 | E43: =SUM(G43,I43,K43,M43) -> 0 | F43: =SUM(H43,J43,L43,N43) -> 0
A44: Raw Materials Inventory | B44: 151 | C44: =E44-F44 -> 0 | E44: =SUM(G44,I44,K44,M44) -> 0 | F44: =SUM(H44,J44,L44,N44) -> 0
A45: Work-In-Process Inventory | B45: 152 | C45: =E45-F45 -> 0 | E45: =SUM(G45,I45,K45,M45) -> 0 | F45: =SUM(H45,J45,L45,N45) -> 0
...

Sheet TB-Aug
A1: Republic of the Philippines
A2: PROVINCE OF AGUSAN DEL SUR
A3: Gov. Democrito O. Plaza Government Center, Prosperidad
A5: TRUST FUND
A6: TRIAL BALANCE
A7: As of August 31, 2011
E9: =A7 -> As of August 31, 2011 | G9: Check Disbursement | I9: Cash Disbursement | K9: Cash Receipts | M9: General Journal
A11: Account Title | B11: Account Code | C11: Debit | D11: Credit | E11: Debit | F11: Credit | G11: Debit | H11: Credit | I11: Debit | J11: Credit | K11: Debit | L11: Credit | M11: Debit | N11: Credit
A13: Cash in Vault | B13: 101 | C13: =E13-F13 -> 0 | E13: =SUM(G13,I13,K13,M13) -> 25269350 | F13: =SUM(H13,J13,L13,N13) -> 25269350 | K13: 25269350 | L13: 25269350
A14: Cash - Collecting Officers | B14: 102 | C14: =E14-F14 -> 0 | E14: =SUM(G14,I14,K14,M14) -> 0 | F14: =SUM(H14,J14,L14,N14) -> 0
A15: Cash Disbursing Officers | B15: 103 | C15: =E15-F15 -> 0 | E15: =SUM(G15,I15,K15,M15) -> 0 | F15: =SUM(H15,J15,L15,N15) -> 0
A16: Petty Cash Fund | B16: 104 | C16: =E16-F16 -> 0 | E16: =SUM(G16,I16,K16,M16) -> 0 | F16: =SUM(H16,J16,L16,N16) -> 0
A17: Payroll Fund | B17: 106 | C17: =E17-F17 -> -0.3 | E17: =SUM(G17,I17,K17,M17) -> 408632.85 | F17: =SUM(H17,J17,L17,N17) -> 408633.15 | G17: 408632.85 | J17: 408632.85 | N17: 0.3
A18: Cash - Bangko Sentral ng Pilipinas | B18: 110 | C18: =E18-F18 -> 0 | E18: =SUM(G18,I18,K18,M18) -> 0 | F18: =SUM(H18,J18,L18,N18) -> 0
A19: Cash in Bank - Local Currency, Current Account | B19: 111 | C19: =E19-F19 -> 33125168 | E19: =SUM(G19,I19,K19,M19) -> 41795058 | F19: =SUM(H19,J19,L19,N19) -> 8669890.2 | H19: 8669890.2 | K19: 25269350 | M19: =16525707.98+0.3 -> 16525708
A20: Cash in Bank - Local Currency, SavingsAccount | B20: 112 | C20: =E20-F20 -> 0 | E20: =SUM(G20,I20,K20,M20) -> 0 | F20: =SUM(H20,J20,L20,N20) -> 0
A21: Cash in Bank - Local Currency, Time Deposits | B21: 113 | C21: =E21-F21 -> 0 | E21: =SUM(G21,I21,K21,M21) -> 0 | F21: =SUM(H21,J21,L21,N21) -> 0
A22: Cash - Bangko Sentral ng Pilipinas | B22: 114 | C22: =E22-F22 -> 0 | E22: =SUM(G22,I22,K22,M22) -> 0 | F22: =SUM(H22,J22,L22,N22) -> 0
A23: Cash in Bank - Foreign Currency, Current Account | B23: 115 | C23: =E23-F23 -> 0 | E23: =SUM(G23,I23,K23,M23) -> 0 | F23: =SUM(H23,J23,L23,N23) -> 0
A24: Cash in Bank - Foreign Currency, Savings Account | B24: 116 | C24: =E24-F24 -> 0 | E24: =SUM(G24,I24,K24,M24) -> 0 | F24: =SUM(H24,J24,L24,N24) -> 0
A25: Cash in Bank - Foreign Currency, Time Deposits | B25: 117 | C25: =E25-F25 -> 0 | E25: =SUM(G25,I25,K25,M25) -> 0 | F25: =SUM(H25,J25,L25,N25) -> 0
A26: Accounts Receivable | B26: 121 | C26: =E26-F26 -> 0 | E26: =SUM(G26,I26,K26,M26) -> 0 | F26: =SUM(H26,J26,L26,N26) -> 0
A27: Allowance for Doubtful Accounts | B27: 301 | C27: =E27-F27 -> 0 | E27: =SUM(G27,I27,K27,M27) -> 0 | F27: =SUM(H27,J27,L27,N27) -> 0
A28: Notes Receivable | B28: 122 | C28: =E28-F28 -> 0 | E28: =SUM(G28,I28,K28,M28) -> 0 | F28: =SUM(H28,J28,L28,N28) -> 0
A29: Due from Officers and Employees | B29: 123 | C29: =E29-F29 -> 0 | E29: =SUM(G29,I29,K29,M29) -> 0 | F29: =SUM(H29,J29,L29,N29) -> 0
A30: Loans Receivable - GOCCs | B30: 124 | C30: =E30-F30 -> 0 | E30: =SUM(G30,I30,K30,M30) -> 0 | F30: =SUM(H30,J30,L30,N30) -> 0
A31: Loans Receivable - LGUs | B31: 125 | C31: =E31-F31 -> 0 | E31: =SUM(G31,I31,K31,M31) -> 0 | F31: =SUM(H31,J31,L31,N31) -> 0
A32: Loans Receivable - Others | B32: 126 | C32: =E32-F32 -> 0 | E32: =SUM(G32,I32,K32,M32) -> 0 | F32: =SUM(H32,J32,L32,N32) -> 0
A33: Real Property Tax Receivable | B33: 127 | C33: =E33-F33 -> 0 | E33: =SUM(G33,I33,K33,M33) -> 0 | F33: =SUM(H33,J33,L33,N33) -> 0
A34: Special Education Tax Receivable | B34: 128 | C34: =E34-F34 -> 0 | E34: =SUM(G34,I34,K34,M34) -> 0 | F34: =SUM(H34,J34,L34,N34) -> 0
A35: Interests Receivable | B35: 129 | C35: =E35-F35 -> 0 | E35: =SUM(G35,I35,K35,M35) -> 0 | F35: =SUM(H35,J35,L35,N35) -> 0
... A37: Due from GOCCs | B37: 137 | C37: =E37-F37 -> 0 | E37: =SUM(G37,I37,K37,M37) -> 0 | F37: =SUM(H37,J37,L37,N37) -> 0
A38: Due from LGUs | B38: 138 | C38: =E38-F38 -> 0 | E38: =SUM(G38,I38,K38,M38) -> 0 | F38: =SUM(H38,J38,L38,N38) -> 0
A39: Due from NGOs/POs | B39: 139 | C39: =E39-F39 -> 0 | E39: =SUM(G39,I39,K39,M39) -> 0 | F39: =SUM(H39,J39,L39,N39) -> 0
A40: Due from Other Funds | B40: 144 | C40: =E40-F40 -> 0 | E40: =SUM(G40,I40,K40,M40) -> 0 | F40: =SUM(H40,J40,L40,N40) -> 0
A41: Receivables - Disallowances/Charges | B41: 146 | C41: =E41-F41 -> 0 | E41: =SUM(G41,I41,K41,M41) -> 0 | F41: =SUM(H41,J41,L41,N41) -> 0
A42: Advances to Officers and Employees | B42: 148 | C42: =E42-F42 -> 50000 | E42: =SUM(G42,I42,K42,M42) -> 50000 | F42: =SUM(H42,J42,L42,N42) -> 0 | G42: 50000
A43: Other Receivables | B43: 149 | C43: =E43-F43 -> 35000 | E43: =SUM(G43,I43,K43,M43) -> 35000 | F43: =SUM(H43,J43,L43,N43) -> 0 | G43: 35000
A44: Raw Materials Inventory | B44: 151 | C44: =E44-F44 -> 0 | E44: =SUM(G44,I44,K44,M44) -> 0 | F44: =SUM(H44,J44,L44,N44) -> 0
A45: Work-In-Process Inventory | B45: 152 | C45: =E45-F45 -> 0 | E45: =SUM(G45,I45,K45,M45) -> 0 | F45: =SUM(H45,J45,L45,N45) -> 0
...

Sheet TB-Sep
A1: Republic of the Philippines
A2: PROVINCE OF AGUSAN DEL SUR
A3: Gov. Democrito O. Plaza Government Center, Prosperidad
A5: TRUST FUND
A6: TRIAL BALANCE
A7: As of September 30, 2011
E9: =A7 -> As of September 30, 2011 | G9: Check Disbursement | I9: Cash Disbursement | K9: Cash Receipts | M9: General Journal
A11: Account Title | B11: Account Code | C11: Debit | D11: Credit | E11: Debit | F11: Credit | G11: Debit | H11: Credit | I11: Debit | J11: Credit | K11: Debit | L11: Credit | M11: Debit | N11: Credit
A13: Cash in Vault | B13: 101 | C13: =E13-F13 -> 0 | E13: =SUM(G13,I13,K13,M13) -> 0 | F13: =SUM(H13,J13,L13,N13) -> 0
A14: Cash - Collecting Officers | B14: 102 | C14: =E14-F14 -> 0 | E14: =SUM(G14,I14,K14,M14) -> 0 | F14: =SUM(H14,J14,L14,N14) -> 0
A15: Cash Disbursing Officers | B15: 103 | C15: =E15-F15 -> 0 | E15: =SUM(G15,I15,K15,M15) -> 0 | F15: =SUM(H15,J15,L15,N15) -> 0
A16: Petty Cash Fund | B16: 104 | C16: =E16-F16 -> 0 | E16: =SUM(G16,I16,K16,M16) -> 0 | F16: =SUM(H16,J16,L16,N16) -> 0
A17: Payroll Fund | B17: 106 | C17: =E17-F17 -> 0 | E17: =SUM(G17,I17,K17,M17) -> 0 | F17: =SUM(H17,J17,L17,N17) -> 0
A18: Cash - Bangko Sentral ng Pilipinas | B18: 110 | C18: =E18-F18 -> 0 | E18: =SUM(G18,I18,K18,M18) -> 0 | F18: =SUM(H18,J18,L18,N18) -> 0
A19: Cash in Bank - Local Currency, Current Account | B19: 111 | C19: =E19-F19 -> 0 | E19: =SUM(G19,I19,K19,M19) -> 0 | F19: =SUM(H19,J19,L19,N19) -> 0
A20: Cash in Bank - Local Currency, SavingsAccount | B20: 112 | C20: =E20-F20 -> 0 | E20: =SUM(G20,I20,K20,M20) -> 0 | F20: =SUM(H20,J20,L20,N20) -> 0
A21: Cash in Bank - Local Currency, Time Deposits | B21: 113 | C21: =E21-F21 -> 0 | E21: =SUM(G21,I21,K21,M21) -> 0 | F21: =SUM(H21,J21,L21,N21) -> 0
A22: Cash - Bangko Sentral ng Pilipinas | B22: 114 | C22: =E22-F22 -> 0 | E22: =SUM(G22,I22,K22,M22) -> 0 | F22: =SUM(H22,J22,L22,N22) -> 0
A23: Cash in Bank - Foreign Currency, Current Account | B23: 115 | C23: =E23-F23 -> 0 | E23: =SUM(G23,I23,K23,M23) -> 0 | F23: =SUM(H23,J23,L23,N23) -> 0
A24: Cash in Bank - Foreign Currency, Savings Account | B24: 116 | C24: =E24-F24 -> 0 | E24: =SUM(G24,I24,K24,M24) -> 0 | F24: =SUM(H24,J24,L24,N24) -> 0
A25: Cash in Bank - Foreign Currency, Time Deposits | B25: 117 | C25: =E25-F25 -> 0 | E25: =SUM(G25,I25,K25,M25) -> 0 | F25: =SUM(H25,J25,L25,N25) -> 0
A26: Accounts Receivable | B26: 121 | C26: =E26-F26 -> 0 | E26: =SUM(G26,I26,K26,M26) -> 0 | F26: =SUM(H26,J26,L26,N26) -> 0
A27: Allowance for Doubtful Accounts | B27: 301 | C27: =E27-F27 -> 0 | E27: =SUM(G27,I27,K27,M27) -> 0 | F27: =SUM(H27,J27,L27,N27) -> 0
A28: Notes Receivable | B28: 122 | C28: =E28-F28 -> 0 | E28: =SUM(G28,I28,K28,M28) -> 0 | F28: =SUM(H28,J28,L28,N28) -> 0
A29: Due from Officers and Employees | B29: 123 | C29: =E29-F29 -> 0 | E29: =SUM(G29,I29,K29,M29) -> 0 | F29: =SUM(H29,J29,L29,N29) -> 0
A30: Loans Receivable - GOCCs | B30: 124 | C30: =E30-F30 -> 0 | E30: =SUM(G30,I30,K30,M30) -> 0 | F30: =SUM(H30,J30,L30,N30) -> 0
A31: Loans Receivable - LGUs | B31: 125 | C31: =E31-F31 -> 0 | E31: =SUM(G31,I31,K31,M31) -> 0 | F31: =SUM(H31,J31,L31,N31) -> 0
A32: Loans Receivable - Others | B32: 126 | C32: =E32-F32 -> 0 | E32: =SUM(G32,I32,K32,M32) -> 0 | F32: =SUM(H32,J32,L32,N32) -> 0
A33: Real Property Tax Receivable | B33: 127 | C33: =E33-F33 -> 0 | E33: =SUM(G33,I33,K33,M33) -> 0 | F33: =SUM(H33,J33,L33,N33) -> 0
A34: Special Education Tax Receivable | B34: 128 | C34: =E34-F34 -> 0 | E34: =SUM(G34,I34,K34,M34) -> 0 | F34: =SUM(H34,J34,L34,N34) -> 0
A35: Interests Receivable | B35: 129 | C35: =E35-F35 -> 0 | E35: =SUM(G35,I35,K35,M35) -> 0 | F35: =SUM(H35,J35,L35,N35) -> 0
... A37: Due from GOCCs | B37: 137 | C37: =E37-F37 -> 0 | E37: =SUM(G37,I37,K37,M37) -> 0 | F37: =SUM(H37,J37,L37,N37) -> 0
A38: Due from LGUs | B38: 138 | C38: =E38-F38 -> 0 | E38: =SUM(G38,I38,K38,M38) -> 0 | F38: =SUM(H38,J38,L38,N38) -> 0
A39: Due from NGOs/POs | B39: 139 | C39: =E39-F39 -> 0 | E39: =SUM(G39,I39,K39,M39) -> 0 | F39: =SUM(H39,J39,L39,N39) -> 0
A40: Due from Other Funds | B40: 144 | C40: =E40-F40 -> 0 | E40: =SUM(G40,I40,K40,M40) -> 0 | F40: =SUM(H40,J40,L40,N40) -> 0
A41: Receivables - Disallowances/Charges | B41: 146 | C41: =E41-F41 -> 0 | E41: =SUM(G41,I41,K41,M41) -> 0 | F41: =SUM(H41,J41,L41,N41) -> 0
A42: Advances to Officers and Employees | B42: 148 | C42: =E42-F42 -> 0 | E42: =SUM(G42,I42,K42,M42) -> 0 | F42: =SUM(H42,J42,L42,N42) -> 0
A43: Other Receivables | B43: 149 | C43: =E43-F43 -> 0 | E43: =SUM(G43,I43,K43,M43) -> 0 | F43: =SUM(H43,J43,L43,N43) -> 0
A44: Raw Materials Inventory | B44: 151 | C44: =E44-F44 -> 0 | E44: =SUM(G44,I44,K44,M44) -> 0 | F44: =SUM(H44,J44,L44,N44) -> 0
A45: Work-In-Process Inventory | B45: 152 | C45: =E45-F45 -> 0 | E45: =SUM(G45,I45,K45,M45) -> 0 | F45: =SUM(H45,J45,L45,N45) -> 0
...

Sheet TB-Oct
A1: Republic of the Philippines
A2: PROVINCE OF AGUSAN DEL SUR
A3: Gov. Democrito O. Plaza Government Center, Prosperidad
A5: TRUST FUND
A6: TRIAL BALANCE
A7: As of October 31, 2011
E9: =A7 -> As of October 31, 2011 | G9: Check Disbursement | I9: Cash Disbursement | K9: Cash Receipts | M9: General Journal
A11: Account Title | B11: Account Code | C11: Debit | D11: Credit | E11: Debit | F11: Credit | G11: Debit | H11: Credit | I11: Debit | J11: Credit | K11: Debit | L11: Credit | M11: Debit | N11: Credit
A13: Cash in Vault | B13: 101 | C13: =E13-F13 -> 0 | E13: =SUM(G13,I13,K13,M13) -> 0 | F13: =SUM(H13,J13,L13,N13) -> 0
A14: Cash - Collecting Officers | B14: 102 | C14: =E14-F14 -> 0 | E14: =SUM(G14,I14,K14,M14) -> 0 | F14: =SUM(H14,J14,L14,N14) -> 0
A15: Cash Disbursing Officers | B15: 103 | C15: =E15-F15 -> 0 | E15: =SUM(G15,I15,K15,M15) -> 0 | F15: =SUM(H15,J15,L15,N15) -> 0
A16: Petty Cash Fund | B16: 104 | C16: =E16-F16 -> 0 | E16: =SUM(G16,I16,K16,M16) -> 0 | F16: =SUM(H16,J16,L16,N16) -> 0
A17: Payroll Fund | B17: 106 | C17: =E17-F17 -> 0 | E17: =SUM(G17,I17,K17,M17) -> 0 | F17: =SUM(H17,J17,L17,N17) -> 0
A18: Cash - Bangko Sentral ng Pilipinas | B18: 110 | C18: =E18-F18 -> 0 | E18: =SUM(G18,I18,K18,M18) -> 0 | F18: =SUM(H18,J18,L18,N18) -> 0
A19: Cash in Bank - Local Currency, Current Account | B19: 111 | C19: =E19-F19 -> 0 | E19: =SUM(G19,I19,K19,M19) -> 0 | F19: =SUM(H19,J19,L19,N19) -> 0
A20: Cash in Bank - Local Currency, SavingsAccount | B20: 112 | C20: =E20-F20 -> 0 | E20: =SUM(G20,I20,K20,M20) -> 0 | F20: =SUM(H20,J20,L20,N20) -> 0
A21: Cash in Bank - Local Currency, Time Deposits | B21: 113 | C21: =E21-F21 -> 0 | E21: =SUM(G21,I21,K21,M21) -> 0 | F21: =SUM(H21,J21,L21,N21) -> 0
A22: Cash - Bangko Sentral ng Pilipinas | B22: 114 | C22: =E22-F22 -> 0 | E22: =SUM(G22,I22,K22,M22) -> 0 | F22: =SUM(H22,J22,L22,N22) -> 0
A23: Cash in Bank - Foreign Currency, Current Account | B23: 115 | C23: =E23-F23 -> 0 | E23: =SUM(G23,I23,K23,M23) -> 0 | F23: =SUM(H23,J23,L23,N23) -> 0
A24: Cash in Bank - Foreign Currency, Savings Account | B24: 116 | C24: =E24-F24 -> 0 | E24: =SUM(G24,I24,K24,M24) -> 0 | F24: =SUM(H24,J24,L24,N24) -> 0
A25: Cash in Bank - Foreign Currency, Time Deposits | B25: 117 | C25: =E25-F25 -> 0 | E25: =SUM(G25,I25,K25,M25) -> 0 | F25: =SUM(H25,J25,L25,N25) -> 0
A26: Accounts Receivable | B26: 121 | C26: =E26-F26 -> 0 | E26: =SUM(G26,I26,K26,M26) -> 0 | F26: =SUM(H26,J26,L26,N26) -> 0
A27: Allowance for Doubtful Accounts | B27: 301 | C27: =E27-F27 -> 0 | E27: =SUM(G27,I27,K27,M27) -> 0 | F27: =SUM(H27,J27,L27,N27) -> 0
A28: Notes Receivable | B28: 122 | C28: =E28-F28 -> 0 | E28: =SUM(G28,I28,K28,M28) -> 0 | F28: =SUM(H28,J28,L28,N28) -> 0
A29: Due from Officers and Employees | B29: 123 | C29: =E29-F29 -> 0 | E29: =SUM(G29,I29,K29,M29) -> 0 | F29: =SUM(H29,J29,L29,N29) -> 0
A30: Loans Receivable - GOCCs | B30: 124 | C30: =E30-F30 -> 0 | E30: =SUM(G30,I30,K30,M30) -> 0 | F30: =SUM(H30,J30,L30,N30) -> 0
A31: Loans Receivable - LGUs | B31: 125 | C31: =E31-F31 -> 0 | E31: =SUM(G31,I31,K31,M31) -> 0 | F31: =SUM(H31,J31,L31,N31) -> 0
A32: Loans Receivable - Others | B32: 126 | C32: =E32-F32 -> 0 | E32: =SUM(G32,I32,K32,M32) -> 0 | F32: =SUM(H32,J32,L32,N32) -> 0
A33: Real Property Tax Receivable | B33: 127 | C33: =E33-F33 -> 0 | E33: =SUM(G33,I33,K33,M33) -> 0 | F33: =SUM(H33,J33,L33,N33) -> 0
A34: Special Education Tax Receivable | B34: 128 | C34: =E34-F34 -> 0 | E34: =SUM(G34,I34,K34,M34) -> 0 | F34: =SUM(H34,J34,L34,N34) -> 0
A35: Interests Receivable | B35: 129 | C35: =E35-F35 -> 0 | E35: =SUM(G35,I35,K35,M35) -> 0 | F35: =SUM(H35,J35,L35,N35) -> 0
... A37: Due from GOCCs | B37: 137 | C37: =E37-F37 -> 0 | E37: =SUM(G37,I37,K37,M37) -> 0 | F37: =SUM(H37,J37,L37,N37) -> 0
A38: Due from LGUs | B38: 138 | C38: =E38-F38 -> 0 | E38: =SUM(G38,I38,K38,M38) -> 0 | F38: =SUM(H38,J38,L38,N38) -> 0
A39: Due from NGOs/POs | B39: 139 | C39: =E39-F39 -> 0 | E39: =SUM(G39,I39,K39,M39) -> 0 | F39: =SUM(H39,J39,L39,N39) -> 0
A40: Due from Other Funds | B40: 144 | C40: =E40-F40 -> 0 | E40: =SUM(G40,I40,K40,M40) -> 0 | F40: =SUM(H40,J40,L40,N40) -> 0
A41: Receivables - Disallowances/Charges | B41: 146 | C41: =E41-F41 -> 0 | E41: =SUM(G41,I41,K41,M41) -> 0 | F41: =SUM(H41,J41,L41,N41) -> 0
A42: Advances to Officers and Employees | B42: 148 | C42: =E42-F42 -> 0 | E42: =SUM(G42,I42,K42,M42) -> 0 | F42: =SUM(H42,J42,L42,N42) -> 0
A43: Other Receivables | B43: 149 | C43: =E43-F43 -> 0 | E43: =SUM(G43,I43,K43,M43) -> 0 | F43: =SUM(H43,J43,L43,N43) -> 0
A44: Raw Materials Inventory | B44: 151 | C44: =E44-F44 -> 0 | E44: =SUM(G44,I44,K44,M44) -> 0 | F44: =SUM(H44,J44,L44,N44) -> 0
A45: Work-In-Process Inventory | B45: 152 | C45: =E45-F45 -> 0 | E45: =SUM(G45,I45,K45,M45) -> 0 | F45: =SUM(H45,J45,L45,N45) -> 0
...

Sheet TB-Nov
A1: Republic of the Philippines
A2: PROVINCE OF AGUSAN DEL SUR
A3: Gov. Democrito O. Plaza Government Center, Prosperidad
A5: TRUST FUND
A6: TRIAL BALANCE
A7: As of November 30, 2011
E9: =A7 -> As of November 30, 2011 | G9: Check Disbursement | I9: Cash Disbursement | K9: Cash Receipts | M9: General Journal
A11: Account Title | B11: Account Code | C11: Debit | D11: Credit | E11: Debit | F11: Credit | G11: Debit | H11: Credit | I11: Debit | J11: Credit | K11: Debit | L11: Credit | M11: Debit | N11: Credit
A13: Cash in Vault | B13: 101 | C13: =E13-F13 -> 0 | E13: =SUM(G13,I13,K13,M13) -> 0 | F13: =SUM(H13,J13,L13,N13) -> 0
A14: Cash - Collecting Officers | B14: 102 | C14: =E14-F14 -> 0 | E14: =SUM(G14,I14,K14,M14) -> 0 | F14: =SUM(H14,J14,L14,N14) -> 0
A15: Cash Disbursing Officers | B15: 103 | C15: =E15-F15 -> 0 | E15: =SUM(G15,I15,K15,M15) -> 0 | F15: =SUM(H15,J15,L15,N15) -> 0
A16: Petty Cash Fund | B16: 104 | C16: =E16-F16 -> 0 | E16: =SUM(G16,I16,K16,M16) -> 0 | F16: =SUM(H16,J16,L16,N16) -> 0
A17: Payroll Fund | B17: 106 | C17: =E17-F17 -> 0 | E17: =SUM(G17,I17,K17,M17) -> 0 | F17: =SUM(H17,J17,L17,N17) -> 0
A18: Cash - Bangko Sentral ng Pilipinas | B18: 110 | C18: =E18-F18 -> 0 | E18: =SUM(G18,I18,K18,M18) -> 0 | F18: =SUM(H18,J18,L18,N18) -> 0
A19: Cash in Bank - Local Currency, Current Account | B19: 111 | C19: =E19-F19 -> 0 | E19: =SUM(G19,I19,K19,M19) -> 0 | F19: =SUM(H19,J19,L19,N19) -> 0
A20: Cash in Bank - Local Currency, SavingsAccount | B20: 112 | C20: =E20-F20 -> 0 | E20: =SUM(G20,I20,K20,M20) -> 0 | F20: =SUM(H20,J20,L20,N20) -> 0
A21: Cash in Bank - Local Currency, Time Deposits | B21: 113 | C21: =E21-F21 -> 0 | E21: =SUM(G21,I21,K21,M21) -> 0 | F21: =SUM(H21,J21,L21,N21) -> 0
A22: Cash - Bangko Sentral ng Pilipinas | B22: 114 | C22: =E22-F22 -> 0 | E22: =SUM(G22,I22,K22,M22) -> 0 | F22: =SUM(H22,J22,L22,N22) -> 0
A23: Cash in Bank - Foreign Currency, Current Account | B23: 115 | C23: =E23-F23 -> 0 | E23: =SUM(G23,I23,K23,M23) -> 0 | F23: =SUM(H23,J23,L23,N23) -> 0
A24: Cash in Bank - Foreign Currency, Savings Account | B24: 116 | C24: =E24-F24 -> 0 | E24: =SUM(G24,I24,K24,M24) -> 0 | F24: =SUM(H24,J24,L24,N24) -> 0
A25: Cash in Bank - Foreign Currency, Time Deposits | B25: 117 | C25: =E25-F25 -> 0 | E25: =SUM(G25,I25,K25,M25) -> 0 | F25: =SUM(H25,J25,L25,N25) -> 0
A26: Accounts Receivable | B26: 121 | C26: =E26-F26 -> 0 | E26: =SUM(G26,I26,K26,M26) -> 0 | F26: =SUM(H26,J26,L26,N26) -> 0
A27: Allowance for Doubtful Accounts | B27: 301 | C27: =E27-F27 -> 0 | E27: =SUM(G27,I27,K27,M27) -> 0 | F27: =SUM(H27,J27,L27,N27) -> 0
A28: Notes Receivable | B28: 122 | C28: =E28-F28 -> 0 | E28: =SUM(G28,I28,K28,M28) -> 0 | F28: =SUM(H28,J28,L28,N28) -> 0
A29: Due from Officers and Employees | B29: 123 | C29: =E29-F29 -> 0 | E29: =SUM(G29,I29,K29,M29) -> 0 | F29: =SUM(H29,J29,L29,N29) -> 0
A30: Loans Receivable - GOCCs | B30: 124 | C30: =E30-F30 -> 0 | E30: =SUM(G30,I30,K30,M30) -> 0 | F30: =SUM(H30,J30,L30,N30) -> 0
A31: Loans Receivable - LGUs | B31: 125 | C31: =E31-F31 -> 0 | E31: =SUM(G31,I31,K31,M31) -> 0 | F31: =SUM(H31,J31,L31,N31) -> 0
A32: Loans Receivable - Others | B32: 126 | C32: =E32-F32 -> 0 | E32: =SUM(G32,I32,K32,M32) -> 0 | F32: =SUM(H32,J32,L32,N32) -> 0
A33: Real Property Tax Receivable | B33: 127 | C33: =E33-F33 -> 0 | E33: =SUM(G33,I33,K33,M33) -> 0 | F33: =SUM(H33,J33,L33,N33) -> 0
A34: Special Education Tax Receivable | B34: 128 | C34: =E34-F34 -> 0 | E34: =SUM(G34,I34,K34,M34) -> 0 | F34: =SUM(H34,J34,L34,N34) -> 0
A35: Interests Receivable | B35: 129 | C35: =E35-F35 -> 0 | E35: =SUM(G35,I35,K35,M35) -> 0 | F35: =SUM(H35,J35,L35,N35) -> 0
... A37: Due from GOCCs | B37: 137 | C37: =E37-F37 -> 0 | E37: =SUM(G37,I37,K37,M37) -> 0 | F37: =SUM(H37,J37,L37,N37) -> 0
A38: Due from LGUs | B38: 138 | C38: =E38-F38 -> 0 | E38: =SUM(G38,I38,K38,M38) -> 0 | F38: =SUM(H38,J38,L38,N38) -> 0
A39: Due from NGOs/POs | B39: 139 | C39: =E39-F39 -> 0 | E39: =SUM(G39,I39,K39,M39) -> 0 | F39: =SUM(H39,J39,L39,N39) -> 0
A40: Due from Other Funds | B40: 144 | C40: =E40-F40 -> 0 | E40: =SUM(G40,I40,K40,M40) -> 0 | F40: =SUM(H40,J40,L40,N40) -> 0
A41: Receivables - Disallowances/Charges | B41: 146 | C41: =E41-F41 -> 0 | E41: =SUM(G41,I41,K41,M41) -> 0 | F41: =SUM(H41,J41,L41,N41) -> 0
A42: Advances to Officers and Employees | B42: 148 | C42: =E42-F42 -> 0 | E42: =SUM(G42,I42,K42,M42) -> 0 | F42: =SUM(H42,J42,L42,N42) -> 0
A43: Other Receivables | B43: 149 | C43: =E43-F43 -> 0 | E43: =SUM(G43,I43,K43,M43) -> 0 | F43: =SUM(H43,J43,L43,N43) -> 0
A44: Raw Materials Inventory | B44: 151 | C44: =E44-F44 -> 0 | E44: =SUM(G44,I44,K44,M44) -> 0 | F44: =SUM(H44,J44,L44,N44) -> 0
A45: Work-In-Process Inventory | B45: 152 | C45: =E45-F45 -> 0 | E45: =SUM(G45,I45,K45,M45) -> 0 | F45: =SUM(H45,J45,L45,N45) -> 0
...

Sheet TB-Dec
A1: Republic of the Philippines
A2: PROVINCE OF AGUSAN DEL SUR
A3: Gov. Democrito O. Plaza Government Center, Prosperidad
A5: TRUST FUND
A6: TRIAL BALANCE
A7: As of December 31, 2011
E9: =A7 -> As of December 31, 2011 | G9: Check Disbursement | I9: Cash Disbursement | K9: Cash Receipts | M9: General Journal
A11: Account Title | B11: Account Code | C11: Debit | D11: Credit | E11: Debit | F11: Credit | G11: Debit | H11: Credit | I11: Debit | J11: Credit | K11: Debit | L11: Credit | M11: Debit | N11: Credit
A13: Cash in Vault | B13: 101 | C13: =E13-F13 -> 0 | E13: =SUM(G13,I13,K13,M13) -> 0 | F13: =SUM(H13,J13,L13,N13) -> 0
A14: Cash - Collecting Officers | B14: 102 | C14: =E14-F14 -> 0 | E14: =SUM(G14,I14,K14,M14) -> 0 | F14: =SUM(H14,J14,L14,N14) -> 0
A15: Cash Disbursing Officers | B15: 103 | C15: =E15-F15 -> 0 | E15: =SUM(G15,I15,K15,M15) -> 0 | F15: =SUM(H15,J15,L15,N15) -> 0
A16: Petty Cash Fund | B16: 104 | C16: =E16-F16 -> 0 | E16: =SUM(G16,I16,K16,M16) -> 0 | F16: =SUM(H16,J16,L16,N16) -> 0
A17: Payroll Fund | B17: 106 | C17: =E17-F17 -> 0 | E17: =SUM(G17,I17,K17,M17) -> 0 | F17: =SUM(H17,J17,L17,N17) -> 0
A18: Cash - Bangko Sentral ng Pilipinas | B18: 110 | C18: =E18-F18 -> 0 | E18: =SUM(G18,I18,K18,M18) -> 0 | F18: =SUM(H18,J18,L18,N18) -> 0
A19: Cash in Bank - Local Currency, Current Account | B19: 111 | C19: =E19-F19 -> 0 | E19: =SUM(G19,I19,K19,M19) -> 0 | F19: =SUM(H19,J19,L19,N19) -> 0
A20: Cash in Bank - Local Currency, SavingsAccount | B20: 112 | C20: =E20-F20 -> 0 | E20: =SUM(G20,I20,K20,M20) -> 0 | F20: =SUM(H20,J20,L20,N20) -> 0
A21: Cash in Bank - Local Currency, Time Deposits | B21: 113 | C21: =E21-F21 -> 0 | E21: =SUM(G21,I21,K21,M21) -> 0 | F21: =SUM(H21,J21,L21,N21) -> 0
A22: Cash - Bangko Sentral ng Pilipinas | B22: 114 | C22: =E22-F22 -> 0 | E22: =SUM(G22,I22,K22,M22) -> 0 | F22: =SUM(H22,J22,L22,N22) -> 0
A23: Cash in Bank - Foreign Currency, Current Account | B23: 115 | C23: =E23-F23 -> 0 | E23: =SUM(G23,I23,K23,M23) -> 0 | F23: =SUM(H23,J23,L23,N23) -> 0
A24: Cash in Bank - Foreign Currency, Savings Account | B24: 116 | C24: =E24-F24 -> 0 | E24: =SUM(G24,I24,K24,M24) -> 0 | F24: =SUM(H24,J24,L24,N24) -> 0
A25: Cash in Bank - Foreign Currency, Time Deposits | B25: 117 | C25: =E25-F25 -> 0 | E25: =SUM(G25,I25,K25,M25) -> 0 | F25: =SUM(H25,J25,L25,N25) -> 0
A26: Accounts Receivable | B26: 121 | C26: =E26-F26 -> 0 | E26: =SUM(G26,I26,K26,M26) -> 0 | F26: =SUM(H26,J26,L26,N26) -> 0
A27: Allowance for Doubtful Accounts | B27: 301 | C27: =E27-F27 -> 0 | E27: =SUM(G27,I27,K27,M27) -> 0 | F27: =SUM(H27,J27,L27,N27) -> 0
A28: Notes Receivable | B28: 122 | C28: =E28-F28 -> 0 | E28: =SUM(G28,I28,K28,M28) -> 0 | F28: =SUM(H28,J28,L28,N28) -> 0
A29: Due from Officers and Employees | B29: 123 | C29: =E29-F29 -> 0 | E29: =SUM(G29,I29,K29,M29) -> 0 | F29: =SUM(H29,J29,L29,N29) -> 0
A30: Loans Receivable - GOCCs | B30: 124 | C30: =E30-F30 -> 0 | E30: =SUM(G30,I30,K30,M30) -> 0 | F30: =SUM(H30,J30,L30,N30) -> 0
A31: Loans Receivable - LGUs | B31: 125 | C31: =E31-F31 -> 0 | E31: =SUM(G31,I31,K31,M31) -> 0 | F31: =SUM(H31,J31,L31,N31) -> 0
A32: Loans Receivable - Others | B32: 126 | C32: =E32-F32 -> 0 | E32: =SUM(G32,I32,K32,M32) -> 0 | F32: =SUM(H32,J32,L32,N32) -> 0
A33: Real Property Tax Receivable | B33: 127 | C33: =E33-F33 -> 0 | E33: =SUM(G33,I33,K33,M33) -> 0 | F33: =SUM(H33,J33,L33,N33) -> 0
A34: Special Education Tax Receivable | B34: 128 | C34: =E34-F34 -> 0 | E34: =SUM(G34,I34,K34,M34) -> 0 | F34: =SUM(H34,J34,L34,N34) -> 0
A35: Interests Receivable | B35: 129 | C35: =E35-F35 -> 0 | E35: =SUM(G35,I35,K35,M35) -> 0 | F35: =SUM(H35,J35,L35,N35) -> 0
... A37: Due from GOCCs | B37: 137 | C37: =E37-F37 -> 0 | E37: =SUM(G37,I37,K37,M37) -> 0 | F37: =SUM(H37,J37,L37,N37) -> 0
A38: Due from LGUs | B38: 138 | C38: =E38-F38 -> 0 | E38: =SUM(G38,I38,K38,M38) -> 0 | F38: =SUM(H38,J38,L38,N38) -> 0
A39: Due from NGOs/POs | B39: 139 | C39: =E39-F39 -> 0 | E39: =SUM(G39,I39,K39,M39) -> 0 | F39: =SUM(H39,J39,L39,N39) -> 0
A40: Due from Other Funds | B40: 144 | C40: =E40-F40 -> 0 | E40: =SUM(G40,I40,K40,M40) -> 0 | F40: =SUM(H40,J40,L40,N40) -> 0
A41: Receivables - Disallowances/Charges | B41: 146 | C41: =E41-F41 -> 0 | E41: =SUM(G41,I41,K41,M41) -> 0 | F41: =SUM(H41,J41,L41,N41) -> 0
A42: Advances to Officers and Employees | B42: 148 | C42: =E42-F42 -> 0 | E42: =SUM(G42,I42,K42,M42) -> 0 | F42: =SUM(H42,J42,L42,N42) -> 0
A43: Other Receivables | B43: 149 | C43: =E43-F43 -> 0 | E43: =SUM(G43,I43,K43,M43) -> 0 | F43: =SUM(H43,J43,L43,N43) -> 0
A44: Raw Materials Inventory | B44: 151 | C44: =E44-F44 -> 0 | E44: =SUM(G44,I44,K44,M44) -> 0 | F44: =SUM(H44,J44,L44,N44) -> 0
A45: Work-In-Process Inventory | B45: 152 | C45: =E45-F45 -> 0 | E45: =SUM(G45,I45,K45,M45) -> 0 | F45: =SUM(H45,J45,L45,N45) -> 0
...

Sheet TB
A1: Republic of the Philippines
A2: PROVINCE OF AGUSAN DEL SUR
A3: Gov. Democrito O. Plaza Government Center, Prosperidad
A5: TRUST FUND
A6: TRIAL BALANCE
A7: As of August 31, 2011
G9: Check Disbursement | I9: Cash Disbursement | K9: Cash Receipts | M9: General Journal
A11: Account Title | B11: Account Code | C11: Debit | D11: Credit | E11: Debit | F11: Credit | G11: Debit | H11: Credit | I11: Debit | J11: Credit | K11: Debit | L11: Credit | M11: Debit | N11: Credit
