Workbook

Sheet TB
A1: Republic of the Philippines
A2: PROVINCE OF AGUSAN DEL SUR
A3: Gov. Democrito O. Plaza Government Center, Prosperidad
A5: TRUST FUND
A6: TRIAL BALANCE
A7: As of January 31, 2011
L9: cash trnsactions
A10: Account Title | B10: Account Code | C10: Total | E10: GENERAL FUND | G10: Debit | H10: Debit Totals | I10: Credit Totals | J10: Credit | L10: Debit | M10: Credit
C11: Debit | D11: Credit | E11: Debit | F11: Credit
A12: Cash in Vault | B12: 101 | C12: =E12+G12+#REF! -> #REF! | G12: =H12-I12 -> 0
A13: Cash - Collecting Officers | B13: 102 | G13: =H13-I13 -> 0
A14: Cash Disbursing Officers | B14: 103 | C14: =E14+G16+#REF! -> #REF! | G14: =H14-I14 -> 0
A15: Petty Cash Fund | B15: 104 | C15: =E15+G15+#REF! -> #REF! | G15: =H15-I15 -> 0
A16: Payroll Fund | B16: 106 | G16: =H16-I16 -> -0.8 | H16: =527771.6 -> 527771.6 | I16: =527771.6+0.8 -> 527772.4 | L16: 527771.6 | M16: =0.8+527771.6 -> 527772.4
A17: Cash - Bangko Sentral ng Pilipinas | B17: 110 | C17: =E17+G17+#REF! -> #REF! | G17: =H17-I17 -> 0
A18: Cash in Bank - Local Currency, Current Account | B18: 111 | C18: =E18+G18+#REF! -> #REF! | G18: =H18-I18 -> 14332535 | H18: =8793653.96+15352900 -> 24146554 | I18: 9814018.6 | L18: =8793653.96+15352900 -> 24146554 | M18: 9814018.6
A19: Cash in Bank - Local Currency, SavingsAccount | B19: 112 | C19: =E19+G19+#REF! -> #REF! | G19: =H19-I19 -> 0
A20: Cash in Bank - Local Currency, Time Deposits | B20: 113 | C20: =E20+G20+#REF! -> #REF! | G20: =H20-I20 -> 0
A21: Cash - Bangko Sentral ng Pilipinas | B21: 114 | C21: =E21+G21+#REF! -> #REF! | G21: =H21-I21 -> 0
A22: Cash in Bank - Foreign Currency, Current Account | B22: 115 | C22: =E22+G22+#REF! -> #REF! | G22: =H22-I22 -> 0
A23: Cash in Bank - Foreign Currency, Savings Account | B23: 116 | C23: =E23+G23+#REF! -> #REF! | G23: =H23-I23 -> 0
A24: Cash in Bank - Foreign Currency, Time Deposits | B24: 117 | C24: =E24+G24+#REF! -> #REF! | G24: =H24-I24 -> 0
A25: Accounts Receivable | B25: 121 | C25: =E25+G25+#REF! -> #REF! | G25: =H25-I25 -> 0
A26: Allowance for Doubtful Accounts | B26: 301 | D26: =F26+J26+#REF! -> #REF! | G26: =H26-I26 -> 0
A27: Notes Receivable | B27: 122 | C27: =E27+G27+#REF! -> #REF! | G27: =H27-I27 -> 0
A28: Due from Officers and Employees | B28: 123 | C28: =E28+G41+#REF! -> #REF! | G28: =H28-I28 -> 0
A29: Loans Receivable - GOCCs | B29: 124 | C29: =E29+G29+#REF! -> #REF! | G29: =H29-I29 -> 0
A30: Loans Receivable - LGUs | B30: 125 | C30: =E30+G30+#REF! -> #REF! | G30: =H30-I30 -> 0
A31: Loans Receivable - Others | B31: 126 | C31: =E31+G31+#REF! -> #REF! | G31: =H31-I31 -> 0
A32: Real Property Tax Receivable | B32: 127 | C32: =E32+G32+#REF! -> #REF! | G32: =H32-I32 -> 0
A33: Special Education Tax Receivable | B33: 128 | C33: =E33+G33+#REF! -> #REF! | G33: =H33-I33 -> 0
A34: Interests Receivable | B34: 129 | C34: =E34+G34+#REF! -> #REF! | G34: =H34-I34 -> 0
A35: Due from NGAs | B35: 136 | C35: =E35+G35+#REF! -> #REF! | G35: =H35-I35 -> 0
A36: Due from GOCCs | B36: 137 | C36: =E36+G36+#REF! -> #REF! | G36: =H36-I36 -> 0
A37: Due from LGUs | B37: 138 | C37: =E37+G37+#REF! -> #REF! | G37: =H37-I37 -> 0
A38: Due from NGOs/POs | B38: 139 | C38: =E38+G38+#REF! -> #REF! | G38: =H38-I38 -> -280000 | I38: =200000+80000 -> 280000 | M38: 200000
A39: Due from Other Funds | B39: 144 | C39: =E39+G39+#REF! -> #REF! | G39: =H39-I39 -> 0
A40: Receivables - Disallowances/Charges | B40: 146 | C40: =E40+G40+#REF! -> #REF! | G40: =H40-I40 -> 0
A41: Advances to Officers and Employees | B41: 148 | G41: =H41-I41 -> 189984.6 | H41: =758250.92 -> 758250.92 | I41: =1608.72+566657.6 -> 568266.32 | L41: 758250.92 | M41: 1608.72
A42: Other Receivables | B42: 149 | C42: =E42+G42+#REF! -> #REF! | G42: =H42-I42 -> 0
...

Sheet CASH FLOWS
A1: Republic of the Philippines
A2: PROVINCE OF AGUSAN DEL SUR
A3: Gov. Democrito O. Plaza Government Center, Prosperidad
A6: STATEMENT OF CASH FLOWS
A7: For the Year Ended December 31, 2010
F9: as of | G9: for
F10: 40513 | G10: 40544 | H10: notes
A11: Cash Flows From Operating Activities
B12: Cash Inflows
C13: Share from Internal Revenue Allotment | H13: CR | I13: 665
C14: Collection from Taxpayers | H14: CR | I14: 581-593, 598-599, 127-128, 129,
C15: Receipts from sale of goods and services | H15: CR | I15: 611-624, 628, 629, 631-644, 648, 649, 666,
C16: Interest Income | E16: =F16+G16 -> 171088.46 | F16: 171088.46 | H16: CR | I16: 664
C17: Dividend Income | E17: =F17+G17 -> 0 | H17: CR | I17: 661
C18: Other Receipts | E18: =F18+G18 -> 2.23816e+08 | F18: 1.9966944e+08 | G18: =TB!M38+TB!M41+TB!M181+TB!M184+TB!M186+TB!M189 -> 24146553 | H18: CR | I18: 601-603, 605, 606, 608-609, 662, 663, 667-671, 678, 679, 652, 656, 657, 121-123, 136-139, 144, 146, 148, 149, 413-418, 424, 426, 427, 439, 451, 452, 455, 403
C19: Total Cash Inflows | E19: =SUM(E16:E18) -> 2.2398709e+08 | F19: 1.9984053e+08 | G19: =G18+G16 -> 24146553
B20: Cash Outflows
C21: Payments to -
D22: Suppliers/Creditors | E22: =F22+G22 -> 7235118.3 | F22: 5041872.3 | G22: =TB!L51+TB!L53 -> 2193246 | H22: DR | I22: 755-765, 151, 154, 155-165, 167-170, 176
D23: Employees | E23: =F23+G23 -> 12955183 | F23: 12196932 | G23: =TB!L41 -> 758250.92 | H23: DR | I23: 701-707, 711-725, 731-734, 738-743, 749, 403, 148
C24: Interest Expense | E24: =F24+G24 -> 0 | H24: DR | I24: 975, 409
C25: Other Disbursements | E25: =F25+G25 -> 1.2439496e+08 | F25: 1.1759165e+08 | G25: =TB!L177+TB!L178+TB!L179+TB!L180+TB!L181+TB!L184+TB!L186+TB!L189 -> 6803305.6 | H25: DR | I25: 751-754, 766-768, 771-775, 778-788, 791-797, 799, 802, 805, 811-815, 818-820, 821-823, 826-827, 829-836, 840-841, 848, 850, 851-857, 860-862, 871-878, 881-884, 891-893, 969, 971, 972, 974, 979, 177-182, 185, 186, 189, 401, 402, 412-418, 424, 426, 427, 429, 439, 138, 139,149
C26: Total Cash Outflows | E26: =SUM(E22:E25) -> 1.4458526e+08 | F26: 1.3483045e+08 | G26: =SUM(G22:G25) -> 9754802.5
B27: Cash Provided by (Used In) | E27: =E19-E26 -> 79401830 | F27: 65010079 | G27: =G19-G26 -> 14391751
A28: Cash Flows From Investing Activities
B29: Cash Inflows
C30: Sale of Property, Plant and Equipment | H30: CR | I30: ALL PPEs disposed net of accu. Depn. Plus gainon sale
C31: Sale of Debt Securities of Other Entities
C32: Collection of Principal on Loans to Other Entities | H32: CR | I32: 124-126
C33: Total Cash Inflows
B34: Cash Outflows
C35: Purchase of Property, Plant and Equipment and Public Infrastructures | E35: =F35+G35 -> 97141070 | F35: 97081854 | G35: =TB!L107 -> 59216.15 | I35: ALL PPEs
C36: Purchase of Debt Securities of the Other Entities | H36: DR | I36: 191, 193, 192, 197, 198
C37: Grant/Loans to other Entities
C38: Total Cash Outflows | E38: =SUM(E35:E37) -> 97141070 | F38: 97081854 | G38: =SUM(G35:G37) -> 59216.15
B39: Cash Provided by (Used In) | E39: =E33-E38 -> -97141070 | F39: -97081854 | G39: =G33-G38 -> -59216.15
A40: Cash Flows From Financing Activities
B41: Cash Inflows
C42: Issuance of Debt Securities | H42: CR | I42: 441-443
C43: Acquisition of Loan | H43: CR | I43: 444-445, 450
...

Sheet BS
A1: Republic of the Philippines
A2: PROVINCE OF AGUSAN DEL SUR
A3: Gov. Democrito O. Plaza Government Center, Prosperidad
A5: TRUST FUND
A6: BALANCE SHEET
A7: =+TB!A7 -> As of January 31, 2011
A9: ASSETS
A10: CURRENT ASSETS
B11: CASH | E11: =+E12+E17+E22 -> #REF! | F11: =+F12+F17+F22 -> 14332535 | G11: =+G12+G17+G22 -> #REF! | H11: =+H12+H17+H22 -> #REF!
C12: Cash on Hand | E12: =SUM(E13:E16) -> #REF! | F12: =SUM(F13:F16) -> -0.8 | G12: =SUM(G13:G16) -> #REF! | H12: =SUM(H13:H16) -> #REF!
D13: Cash in Vault | E13: =SUM(F13:H13) -> #REF! | F13: =TB!G12 -> 0 | G13: =[1]Sheet1!K13 -> #REF! | H13: =[1]Sheet1!M13 -> #REF!
D14: Cash - Collecting Officers | E14: =SUM(F14:H14) -> 0 | F14: =TB!G13 -> 0
D15: Cash - Disbursing Officers | E15: =SUM(F15:H15) -> #REF! | F15: =TB!G14 -> 0 | G15: =[1]Sheet1!K15 -> #REF! | H15: =[1]Sheet1!M15 -> #REF!
D16: Payroll Fund | E16: =SUM(F16:H16) -> #REF! | F16: =TB!G16 -> -0.8 | G16: =[1]Sheet1!K16 -> #REF! | H16: =[1]Sheet1!M16 -> #REF!
C17: Cash in Bank - Local Currency | E17: =SUM(E18:E21) -> #REF! | F17: =SUM(F18:F21) -> 14332535 | G17: =SUM(G18:G21) -> #REF! | H17: =SUM(H18:H21) -> #REF!
D18: Cash - Bangko Sentral ng Pilipinas | E18: =SUM(F18:H18) -> #REF! | F18: =TB!G17 -> 0 | G18: =[1]Sheet1!K17 -> #REF! | H18: =[1]Sheet1!M17 -> #REF!
D19: Cash in Bank - Local Currency, Current Account | E19: =SUM(F19:H19) -> #REF! | F19: =TB!G18 -> 14332535 | G19: =[1]Sheet1!K18 -> #REF! | H19: =[1]Sheet1!M18 -> #REF!
D20: Cash in Bank - Local Currency, Savings Account | E20: =SUM(F20:H20) -> #REF! | F20: =TB!G19 -> 0 | G20: =[1]Sheet1!K19 -> #REF! | H20: =[1]Sheet1!M19 -> #REF!
D21: Cash in Bank - Local Currency, Time Deposits | E21: =SUM(F21:H21) -> #REF! | F21: =TB!G20 -> 0 | G21: =[1]Sheet1!K20 -> #REF! | H21: =[1]Sheet1!M20 -> #REF!
C22: Cash in Bank - Foreign Currency | E22: =SUM(E23:E26) -> #REF! | F22: =SUM(F23:F26) -> 0 | G22: =SUM(G23:G26) -> #REF! | H22: =SUM(H23:H26) -> #REF!
D23: Cash - Bangko Sentral ng Pilipinas | E23: =SUM(F23:H23) -> #REF! | F23: =TB!G21 -> 0 | G23: =[1]Sheet1!K21 -> #REF! | H23: =[1]Sheet1!M21 -> #REF!
D24: Cash in Bank - Foreign Currency, Current Account | E24: =SUM(F24:H24) -> #REF! | F24: =TB!G22 -> 0 | G24: =[1]Sheet1!K22 -> #REF! | H24: =[1]Sheet1!M22 -> #REF!
D25: Cash in Bank - Foreign Currency, Savings Account | E25: =SUM(F25:H25) -> #REF! | F25: =TB!G23 -> 0 | G25: =[1]Sheet1!K23 -> #REF! | H25: =[1]Sheet1!M23 -> #REF!
D26: Cash in Bank - Foreign Currency, Time Deposits | E26: =SUM(F26:H26) -> #REF! | F26: =TB!G24 -> 0 | G26: =[1]Sheet1!K24 -> #REF! | H26: =[1]Sheet1!M24 -> #REF!
B27: RECEIVABLES | E27: =+E28+E39+E44+E46 -> #REF! | F27: =+F28+F39+F44+F46 -> -90015.4 | G27: =+G28+G39+G44+G46 -> #REF! | H27: =+H28+H39+H44+H46 -> #REF!
C28: Receivable Accounts | E28: =SUM(E31:E38)+E29-E30 -> #REF! | F28: =SUM(F31:F38)+F29-F30 -> 189984.6 | G28: =SUM(G31:G38)+G29-G30 -> #REF! | H28: =SUM(H31:H38)+H29-H30 -> #REF!
D29: Accounts Receivable | E29: =SUM(F29:H29) -> #REF! | F29: =TB!G25 -> 0 | G29: =[1]Sheet1!K25 -> #REF! | H29: =[1]Sheet1!M25 -> #REF!
D30: Allowance for Doubtful Accounts | E30: =SUM(F30:H30) -> #REF! | F30: =TB!G26 -> 0 | G30: =[1]Sheet1!L26 -> #REF! | H30: =[1]Sheet1!N26 -> #REF!
D31: Notes Receivable | E31: =SUM(F31:H31) -> #REF! | F31: =TB!G27 -> 0 | G31: =[1]Sheet1!K27 -> #REF! | H31: =[1]Sheet1!M27 -> #REF!
D32: Advances to Officers & Employees | E32: =SUM(F32:H32) -> #REF! | F32: =TB!G41 -> 189984.6 | G32: =[1]Sheet1!K28 -> #REF! | H32: =[1]Sheet1!M28 -> #REF!
D33: Loans Receivable - GOCCs | E33: =SUM(F33:H33) -> #REF! | F33: =TB!G29 -> 0 | G33: =[1]Sheet1!K29 -> #REF! | H33: =[1]Sheet1!M29 -> #REF!
D34: Loans Receivable - LGUs | E34: =SUM(F34:H34) -> #REF! | F34: =TB!G30 -> 0 | G34: =[1]Sheet1!K30 -> #REF! | H34: =[1]Sheet1!M30 -> #REF!
D35: Loans Receivable - Others | E35: =SUM(F35:H35) -> #REF! | F35: =TB!G31 -> 0 | G35: =[1]Sheet1!K31 -> #REF! | H35: =[1]Sheet1!M31 -> #REF!
D36: Real Property Tax Receivable | E36: =SUM(F36:H36) -> #REF! | F36: =TB!G32 -> 0 | G36: =[1]Sheet1!K32 -> #REF! | H36: =[1]Sheet1!M32 -> #REF!
D37: Special Education Tax Receivable | E37: =SUM(F37:H37) -> #REF! | F37: =TB!G33 -> 0 | G37: =[1]Sheet1!K33 -> #REF! | H37: =[1]Sheet1!M33 -> #REF!
D38: Interests Receivable | E38: =SUM(F38:H38) -> #REF! | F38: =TB!G34 -> 0 | G38: =[1]Sheet1!K34 -> #REF! | H38: =[1]Sheet1!M34 -> #REF!
C39: Inter-Agency Receivables | E39: =SUM(E40:E43) -> #REF! | F39: =SUM(F40:F43) -> -280000 | G39: =SUM(G40:G43) -> #REF! | H39: =SUM(H40:H43) -> #REF!
D40: Due from NGAs | E40: =SUM(F40:H40) -> #REF! | F40: =TB!G35 -> 0 | G40: =[1]Sheet1!K35 -> #REF! | H40: =[1]Sheet1!M35 -> #REF!
D41: Due from GOCCs | E41: =SUM(F41:H41) -> #REF! | F41: =TB!G36 -> 0 | G41: =[1]Sheet1!K36 -> #REF! | H41: =[1]Sheet1!M36 -> #REF!
D42: Due from LGUs | E42: =SUM(F42:H42) -> #REF! | F42: =TB!G37 -> 0 | G42: =[1]Sheet1!K37 -> #REF! | H42: =[1]Sheet1!M37 -> #REF!
...

Sheet Comparative BS
A1: Republic of the Philippines
A2: PROVINCE OF AGUSAN DEL SUR
A3: Gov. Democrito O. Plaza Government Center, Prosperidad
A5: BALANCE SHEET
A6: TRUST FUND
A7: =+TB!A7 -> As of January 31, 2011
A8: (With Comparative Figures for CY 2009)
F10: 2010 | G10: 2009
A11: ASSETS
A12: CURRENT ASSETS
B13: CASH | E13: =+E14+E19+E24 -> #REF! | F13: =+F14+F19+F24 -> 14332535 | G13: =+G14+G19+G24 -> 1.065559e+08 | H13: =+H14+H19+H24 -> #REF! | I13: =+G13-[2]BS!$F$11 -> 0
C14: Cash on Hand | E14: =SUM(E15:E18) -> #REF! | F14: =SUM(F15:F18) -> -0.8 | G14: =SUM(G15:G18) -> 11756.52 | H14: =SUM(H15:H18) -> #REF! | I14: =+G14-[2]BS!$F$12 -> 0
D15: Cash in Vault | E15: =SUM(F15:H15) -> #REF! | F15: =TB!G12 -> 0 | G15: =[2]TB!G12 -> 0 | H15: =[1]Sheet1!M13 -> #REF! | I15: =+G15-[2]BS!$F$11 -> -1.065559e+08
D16: Cash - Collecting Officers | E16: =SUM(F16:H16) -> 0 | F16: =TB!G13 -> 0 | G16: =[2]TB!G13 -> 0 | I16: =+G16-[2]BS!$F$11 -> -1.065559e+08
D17: Cash - Disbursing Officers | E17: =SUM(F17:H17) -> #REF! | F17: =TB!G14 -> 0 | G17: =[2]TB!G14 -> 0 | H17: =[1]Sheet1!M15 -> #REF! | I17: =+G17-[2]BS!$F$11 -> -1.065559e+08
D18: Payroll Fund | E18: =SUM(F18:H18) -> #REF! | F18: =TB!G16 -> -0.8 | G18: =[2]TB!G16 -> 11756.52 | H18: =[1]Sheet1!M16 -> #REF! | I18: =+G18-[2]BS!$F$16 -> 0
C19: Cash in Bank - Local Currency | E19: =SUM(E20:E23) -> #REF! | F19: =SUM(F20:F23) -> 14332535 | G19: =SUM(G20:G23) -> 1.0654414e+08 | H19: =SUM(H20:H23) -> #REF! | I19: =+G19-[2]BS!$F$17 -> 0
D20: Cash - Bangko Sentral ng Pilipinas | E20: =SUM(F20:H20) -> #REF! | F20: =TB!G17 -> 0 | G20: =[2]TB!G17 -> 0 | H20: =[1]Sheet1!M17 -> #REF! | I20: =+G20-[2]BS!$F$11 -> -1.065559e+08
D21: Cash in Bank - Local Currency, Current Account | E21: =SUM(F21:H21) -> #REF! | F21: =TB!G18 -> 14332535 | G21: =[2]TB!G18 -> 1.0220902e+08 | H21: =[1]Sheet1!M18 -> #REF! | I21: =+G21-[2]BS!$F$19 -> 0
D22: Cash in Bank - Local Currency, Savings Account | E22: =SUM(F22:H22) -> #REF! | F22: =TB!G19 -> 0 | G22: =[2]TB!G19 -> 4335118.1 | H22: =[1]Sheet1!M19 -> #REF! | I22: =+G22-[2]BS!$F$20 -> 0
D23: Cash in Bank - Local Currency, Time Deposits | E23: =SUM(F23:H23) -> #REF! | F23: =TB!G20 -> 0 | G23: =[2]TB!G20 -> 0 | H23: =[1]Sheet1!M20 -> #REF! | I23: =+G23-[2]BS!$F$11 -> -1.065559e+08
C24: Cash in Bank - Foreign Currency | E24: =SUM(E25:E28) -> #REF! | F24: =SUM(F25:F28) -> 0 | G24: =SUM(G25:G28) -> 0 | H24: =SUM(H25:H28) -> #REF! | I24: =+G24-[2]BS!$F$11 -> -1.065559e+08
D25: Cash - Bangko Sentral ng Pilipinas | E25: =SUM(F25:H25) -> #REF! | F25: =TB!G21 -> 0 | G25: =[2]TB!G21 -> 0 | H25: =[1]Sheet1!M21 -> #REF! | I25: =+G25-[2]BS!$F$11 -> -1.065559e+08
D26: Cash in Bank - Foreign Currency, Current Account | E26: =SUM(F26:H26) -> #REF! | F26: =TB!G22 -> 0 | G26: =[2]TB!G22 -> 0 | H26: =[1]Sheet1!M22 -> #REF! | I26: =+G26-[2]BS!$F$11 -> -1.065559e+08
D27: Cash in Bank - Foreign Currency, Savings Account | E27: =SUM(F27:H27) -> #REF! | F27: =TB!G23 -> 0 | G27: =[2]TB!G23 -> 0 | H27: =[1]Sheet1!M23 -> #REF! | I27: =+G27-[2]BS!$F$11 -> -1.065559e+08
D28: Cash in Bank - Foreign Currency, Time Deposits | E28: =SUM(F28:H28) -> #REF! | F28: =TB!G24 -> 0 | G28: =[2]TB!G24 -> 0 | H28: =[1]Sheet1!M24 -> #REF! | I28: =+G28-[2]BS!$F$11 -> -1.065559e+08
B29: RECEIVABLES | E29: =+E30+E41+E46+E48 -> #REF! | F29: =+F30+F41+F46+F48 -> -90015.4 | G29: =+G30+G41+G46+G48 -> 35446067 | H29: =+H30+H41+H46+H48 -> #REF! | I29: =+G29-[2]BS!$F$27 -> 0
C30: Receivable Accounts | E30: =SUM(E33:E40)+E31-E32 -> #REF! | F30: =SUM(F33:F40)+F31-F32 -> 189984.6 | G30: =SUM(G33:G40)+G31-G32 -> 31847669 | H30: =SUM(H33:H40)+H31-H32 -> #REF! | I30: =+G30-[2]BS!$F$28 -> 0
D31: Accounts Receivable | E31: =SUM(F31:H31) -> #REF! | F31: =TB!G25 -> 0 | G31: =[2]TB!G25 -> 0 | H31: =[1]Sheet1!M25 -> #REF! | I31: =+G31-[2]BS!$F$11 -> -1.065559e+08
D32: Allowance for Doubtful Accounts | E32: =SUM(F32:H32) -> #REF! | F32: =TB!G26 -> 0 | G32: =[2]TB!G26 -> 0 | H32: =[1]Sheet1!N26 -> #REF! | I32: =+G32-[2]BS!$F$11 -> -1.065559e+08
D33: Notes Receivable | E33: =SUM(F33:H33) -> #REF! | F33: =TB!G27 -> 0 | G33: =[2]TB!G27 -> 0 | H33: =[1]Sheet1!M27 -> #REF! | I33: =+G33-[2]BS!$F$11 -> -1.065559e+08
D34: Advances to Officers & Employees | E34: =SUM(F34:H34) -> #REF! | F34: =TB!G41 -> 189984.6 | G34: =[2]TB!G41 -> 31847669 | H34: =[1]Sheet1!M28 -> #REF! | I34: =+G34-[2]BS!$F$32 -> 0
D35: Loans Receivable - GOCCs | E35: =SUM(F35:H35) -> #REF! | F35: =TB!G29 -> 0 | G35: =[2]TB!G29 -> 0 | H35: =[1]Sheet1!M29 -> #REF! | I35: =+G35-[2]BS!$F$11 -> -1.065559e+08
D36: Loans Receivable - LGUs | E36: =SUM(F36:H36) -> #REF! | F36: =TB!G30 -> 0 | G36: =[2]TB!G30 -> 0 | H36: =[1]Sheet1!M30 -> #REF! | I36: =+G36-[2]BS!$F$11 -> -1.065559e+08
D37: Loans Receivable - Others | E37: =SUM(F37:H37) -> #REF! | F37: =TB!G31 -> 0 | G37: =[2]TB!G31 -> 0 | H37: =[1]Sheet1!M31 -> #REF! | I37: =+G37-[2]BS!$F$11 -> -1.065559e+08
D38: Real Property Tax Receivable | E38: =SUM(F38:H38) -> #REF! | F38: =TB!G32 -> 0 | G38: =[2]TB!G32 -> 0 | H38: =[1]Sheet1!M32 -> #REF! | I38: =+G38-[2]BS!$F$11 -> -1.065559e+08
D39: Special Education Tax Receivable | E39: =SUM(F39:H39) -> #REF! | F39: =TB!G33 -> 0 | G39: =[2]TB!G33 -> 0 | H39: =[1]Sheet1!M33 -> #REF! | I39: =+G39-[2]BS!$F$11 -> -1.065559e+08
D40: Interests Receivable | E40: =SUM(F40:H40) -> #REF! | F40: =TB!G34 -> 0 | G40: =[2]TB!G34 -> 0 | H40: =[1]Sheet1!M34 -> #REF! | I40: =+G40-[2]BS!$F$11 -> -1.065559e+08
C41: Inter-Agency Receivables | E41: =SUM(E42:E45) -> #REF! | F41: =SUM(F42:F45) -> -280000 | G41: =SUM(G42:G45) -> 3285964.4 | H41: =SUM(H42:H45) -> #REF! | I41: =+G41-[2]BS!$F$39 -> 0
D42: Due from NGAs | E42: =SUM(F42:H42) -> #REF! | F42: =TB!G35 -> 0 | G42: =[2]TB!G35 -> 0 | H42: =[1]Sheet1!M35 -> #REF! | I42: =+G42-[2]BS!$F$11 -> -1.065559e+08
...

Sheet SIE
A1: Republic of the Philippines
A2: PROVINCE OF AGUSAN DEL SUR
A3: Gov. Democrito O. Plaza Government Center, Prosperidad
A5: GENERAL FUND PROPER
A6: STATEMENT OF INCOME AND EXPENSES
A7: For the quarter ended June 30, 2009
A10: TAX REVENUE
B11: Local Taxes | G11: =SUM(G12:G27) -> #REF! | H11: =SUM(H12:H27) -> 0 | I11: =SUM(I12:I27) -> #REF! | J11: =SUM(J12:J27) -> #REF!
C12: Professional Tax | G12: =SUM(H12:J12) -> #REF! | H12: =TB!J204 -> 0 | I12: =[1]Sheet1!L204 -> #REF! | J12: =[1]Sheet1!N204 -> #REF!
C13: Amusement Tax | G13: =SUM(H13:J13) -> 0 | H13: =TB!J205 -> 0
C14: Business Tax | G14: =SUM(H14:J14) -> #REF! | H14: =TB!J206 -> 0 | I14: =[1]Sheet1!L205 -> #REF! | J14: =[1]Sheet1!N205 -> #REF!
C15: Community Tax | G15: =SUM(H15:J15) -> #REF! | H15: =TB!J207 -> 0 | I15: =[1]Sheet1!L206 -> #REF! | J15: =[1]Sheet1!N206 -> #REF!
C16: Franchise Tax | G16: =SUM(H16:J16) -> #REF! | H16: =TB!J208 -> 0 | I16: =[1]Sheet1!L207 -> #REF! | J16: =[1]Sheet1!N207 -> #REF!
C17: Occupation Tax ** | G17: =SUM(H17:J17) -> #REF! | H17: =TB!J209 -> 0 | I17: =[1]Sheet1!L208 -> #REF! | J17: =[1]Sheet1!N208 -> #REF!
C18: Printing and Publication Tax | G18: =SUM(H18:J18) -> #REF! | H18: =TB!J210 -> 0 | I18: =[1]Sheet1!L209 -> #REF! | J18: =[1]Sheet1!N209 -> #REF!
C19: Property Transfer Tax | G19: =SUM(H19:J19) -> #REF! | H19: =TB!J211 -> 0 | I19: =[1]Sheet1!L210 -> #REF! | J19: =[1]Sheet1!N210 -> #REF!
C20: Real Property Tax | G20: =SUM(H20:J20) -> #REF! | H20: =TB!J212 -> 0 | I20: =[1]Sheet1!L211 -> #REF! | J20: =[1]Sheet1!N211 -> #REF!
C21: Real Property Tax on Idle Lands | G21: =SUM(H21:J21) -> #REF! | H21: =TB!J213 -> 0 | I21: =[1]Sheet1!L212 -> #REF! | J21: =[1]Sheet1!N212 -> #REF!
C22: Special Assessment Tax | G22: =SUM(H22:J22) -> #REF! | H22: =TB!J214 -> 0 | I22: =[1]Sheet1!L213 -> #REF! | J22: =[1]Sheet1!N213 -> #REF!
C23: Special Education Tax | G23: =SUM(H23:J23) -> #REF! | H23: =TB!J215 -> 0 | I23: =[1]Sheet1!L214 -> #REF! | J23: =[1]Sheet1!N214 -> #REF!
C24: Tax on Delivery Trucks and Vans | G24: =SUM(H24:J24) -> #REF! | H24: =TB!J216 -> 0 | I24: =[1]Sheet1!L215 -> #REF! | J24: =[1]Sheet1!N215 -> #REF!
C25: Tax on Sand, Gravel and Other Quarry Products | G25: =SUM(H25:J25) -> #REF! | H25: =TB!J217 -> 0 | I25: =[1]Sheet1!L216 -> #REF! | J25: =[1]Sheet1!N216 -> #REF!
... C27: Fines and Penalties - Local Taxes | G27: =SUM(H27:J27) -> #REF! | H27: =TB!J219 -> 0 | I27: =[1]Sheet1!L218 -> #REF! | J27: =[1]Sheet1!N218 -> #REF!
A28: GENERAL INCOME ACCOUNTS | G28: =+G29+G38+G55+G76 -> #REF! | H28: =+H29+H38+H55+H76 -> 0 | I28: =+I29+I38+I55+I76 -> #REF! | J28: =+J29+J38+J55+J76 -> #REF!
B29: Permits and Licenses | G29: =SUM(G30:G37) -> #REF! | H29: =SUM(H30:H37) -> 0 | I29: =SUM(I30:I37) -> #REF! | J29: =SUM(J30:J37) -> #REF!
C30: Fees on Weights and Measures | G30: =SUM(H30:J30) -> #REF! | H30: =TB!J220 -> 0 | I30: =[1]Sheet1!L219 -> #REF! | J30: =[1]Sheet1!N219 -> #REF!
C31: Fishery Rental Fees | G31: =SUM(H31:J31) -> #REF! | H31: =TB!J221 -> 0 | I31: =[1]Sheet1!L220 -> #REF! | J31: =[1]Sheet1!N220 -> #REF!
C32: Franchising and Licensing Fees | G32: =SUM(H32:J32) -> #REF! | H32: =TB!J222 -> 0 | I32: =[1]Sheet1!L221 -> #REF! | J32: =[1]Sheet1!N221 -> #REF!
C33: Motor Vehicles Users Charge | G33: =SUM(H33:J33) -> #REF! | H33: =TB!J223 -> 0 | I33: =[1]Sheet1!L222 -> #REF! | J33: =[1]Sheet1!N222 -> #REF!
C34: Permit Fees | G34: =SUM(H34:J34) -> #REF! | H34: =TB!J224 -> 0 | I34: =[1]Sheet1!L223 -> #REF! | J34: =[1]Sheet1!N223 -> #REF!
C35: Registration Fees | G35: =SUM(H35:J35) -> #REF! | H35: =TB!J225 -> 0 | I35: =[1]Sheet1!L224 -> #REF! | J35: =[1]Sheet1!N224 -> #REF!
C36: Other Permits and Licenses | G36: =SUM(H36:J36) -> #REF! | H36: =TB!J226 -> 0 | I36: =[1]Sheet1!L225 -> #REF! | J36: =[1]Sheet1!N225 -> #REF!
C37: Fines and Penalties - Permits and Licenses | G37: =SUM(H37:J37) -> #REF! | H37: =TB!J227 -> 0 | I37: =[1]Sheet1!L226 -> #REF! | J37: =[1]Sheet1!N226 -> #REF!
B38: Service Income | G38: =SUM(G39:G54) -> #REF! | H38: =SUM(H39:H54) -> 0 | I38: =SUM(I39:I54) -> #REF! | J38: =SUM(J39:J54) -> #REF!
C39: Affiliation Fees | G39: =SUM(H39:J39) -> #REF! | H39: =TB!J228 -> 0 | I39: =[1]Sheet1!L227 -> #REF! | J39: =[1]Sheet1!N227 -> #REF!
C40: Athletic and Cultural Fees | G40: =SUM(H40:J40) -> #REF! | H40: =TB!J229 -> 0 | I40: =[1]Sheet1!L228 -> #REF! | J40: =[1]Sheet1!N228 -> #REF!
C41: Clearance and Certification Fees | G41: =SUM(H41:J41) -> #REF! | H41: =TB!J230 -> 0 | I41: =[1]Sheet1!L229 -> #REF! | J41: =[1]Sheet1!N229 -> #REF!
C42: Comprehensive Examination Fees | G42: =SUM(H42:J42) -> #REF! | H42: =TB!J231 -> 0 | I42: =[1]Sheet1!L230 -> #REF! | J42: =[1]Sheet1!N230 -> #REF!
C43: Diploma and Graduation Fees | G43: =SUM(H43:J43) -> #REF! | H43: =TB!J232 -> 0 | I43: =[1]Sheet1!L231 -> #REF! | J43: =[1]Sheet1!N231 -> #REF!
C44: Garbage Fees | G44: =SUM(H44:J44) -> #REF! | H44: =TB!J233 -> 0 | I44: =[1]Sheet1!L232 -> #REF! | J44: =[1]Sheet1!N232 -> #REF!
...

Sheet SGE
A1: Republic of the Philippines
A2: PROVINCE OF AGUSAN DEL SUR
A3: Gov. Democrito O. Plaza Government Center, Prosperidad
A5: GENERAL FUND PROPER
A6: STATEMENT OF GOVERNMENT EQUITY
A7: For the year ended 2009
A12: Government Equity, Beginning Balance | B12: =SUM(C12:E12) -> #REF! | D12: =D40 -> #REF! | E12: =E40 -> #REF!
A13: (per BS, as of December 31, 2007)
A14: Add Retained Operating Surplus: | B14: =SUM(B15:B16) -> #REF! | D14: =SUM(D15:D16) -> #REF! | E14: =SUM(E15:E16) -> #REF!
A15: Current Operations (Net Income/Loss per SIE) | B15: =SUM(C15:E15) -> #REF! | C15: =SIE!H321 -> 0 | D15: =[1]Sheet1!I320 -> #REF! | E15: =[1]Sheet1!J320 -> #REF!
A16: Prior Years’ Adjustments (Bal.per Pre-closing Trial Balance) | B16: =SUM(C16:E16) -> #REF! | C16: =-TB!G280 -> 0 | D16: =+D36 -> #REF! | E16: =+E36 -> #REF! | F16: =C15+C16 -> 0
A17: Less: Transfer of Public Infrastructure | B17: =SUM(C17:E17) -> #REF! | C17: =SUM([3]PRE!G183) -> 0 | D17: =SUM([1]Sheet1!J146:J155) -> #REF! | E17: =SUM([1]Sheet1!K146:K155) -> #REF!
A18: TOTAL | F18: =F12+F16 -> 0
A19: Add/Deduct: Transfer from( to)
A20: Transfer of PPE/Completed projects from Trust
A21: Fund/General Fund/Other Fund
A22: Transfer of PPE/Completed projects to General Fund/Other Fund
A23: Transfer of completed Projects to Registry:
A24: Public Infrastructure | C24: 0
A25: Reforestation Projects
A26: Transfer of PPE/completed projects from Other LGU
A27: Transfer of PPE/completed projects to Other LGUs
A28: Other Adjustments | F28: =SUM(C20:C24) -> 0
A29: Government Equity, Ending Balance
A30: (per BS as of December 31, 2008 ) | F30: =F18+F28 -> 0
A35: Computations:
A36: 1) Prior Years' Adjustments | B36: =+B38-B37 -> #REF! | C36: =+C38-C37 -> 14987551 | D36: =+D38-D37 -> #REF! | E36: =+E38-E37 -> #REF!
A37: Debit Balance | B37: =SUM(C37:E37) -> #REF! | C37: 0 | D37: =+[1]Sheet1!K278 -> #REF! | E37: =+[1]Sheet1!M278 -> #REF!
A38: Credit Balance | B38: =SUM(C38:E38) -> #REF! | C38: =[3]PRE!J203 -> 14987551 | D38: =+[1]Sheet1!L278 -> #REF! | E38: =+[1]Sheet1!N278 -> #REF!
A40: 2) Government Equity, Jan. 1 | B40: =+B42-B41 -> #REF! | C40: =+C42-C41 -> 2.5351169e+08 | D40: =+D42-D41 -> #REF! | E40: =+E42-E41 -> #REF!
A41: Debit Balance | B41: =SUM(C41:E41) -> #REF! | C41: =[4]tb!$J$198 -> 4.9353478e+08 | D41: =+[1]Sheet1!K198 -> #REF! | E41: =+[1]Sheet1!M198 -> #REF!
A42: Credit Balance | B42: =SUM(C42:E42) -> #REF! | C42: =[3]PRE!J194 -> 7.4704647e+08 | D42: =+[1]Sheet1!L198 -> #REF! | E42: =+[1]Sheet1!N198 -> #REF!
A45: Certified Correct:
A49: JOY D. LAGAT, CPA
A50: Accountant-IV
A51: Officer in charge

Sheet schedule
A1: Republic of the Philippines
A2: PROVINCE OF AGUSAN DEL SUR
A3: Gov. Democrito O. Plaza Government Center, Prosperidad
A5: TRUST FUND
A6: SCHEDULE
A7: =+TB!A7 -> As of January 31, 2011
A9: Schedule 1 - 106- Payroll Fund
C10: Corazon Canda | E10: =92515.04-92515.04 -> 0
C11: Evangeline Cabalan | E11: =19911.05-370154.28+357554.28-735562.83+735464.31+671055.63-670356.58+502907.22+0.4-502932.43+278954.03-278954.03+350636.97-350636.97+61826.69-61761.69+276593.53-276593.62+121469.22-121469.22-60869.63+60869.63+99114.14-99114.14+442158.01-442158.01+253268.81-253268.81+373409.17-373409.17+199934.06-199934.06+151582.91-151582.91+113162.43-113162.43 -> 7951.68
C12: Josefina Tado | E12: =3804.84-166413.19+156413.19+10000-247864.3+322435.3+416530.57-491101.57+117942.65-117942.65+153319.07-153319.07+108071.63-106071.63-2000 -> 3804.84
C13: Corazon Canda | E13: =216876.22-216896.22+197933.2-197933.2+466695.11-466695.11+637006.02-637006.02+396756.51-396756.51-978711.86+978712.66+522640.6-522520.6-464+1281293.05-1280629.05-0.8+527771.6-527771.6 -> 300
E14: =SUM(E10:E13) -> 12056.52 | F14: =+E14-TB!G16 -> 12057.32
A16: Schedule 2 - 111- CASH IN BANK-LCCA
C17: (1) LBP | D17: -UNICEF | E17: =209901.89+539600-566506.88-10000+18268+767093-246754.32+806.46-301097.08-229320.48+1025+3090-91733.08-10481.18+667600-205673.82+48-80000-25500+1723420-459126.25+663690-296475-148808.8+4958.8-565020-0.5-504386.22+5301.82+8400-397345.6-306591.5+150000+17035.72-35610-8200-67556.5+498400-5700-32200-35170.4+164-218603.04-119.6+5980-43769.96+852900 -> 1245932.5
C18: PNB | D18: -Proper | E18: 37145.34
C19: (3) PNB | D19: -PCSO Funds | E19: =10152.77+13119.82+20133.47+33458.78+5+45600+79455.31 -> 201925.15
C20: (4) LBP | D20: -UNDP | E20: 466.98
C21: (5) LBP | D21: -LDAP-RPT | E21: 1160.35
C22: (7) LBP | D22: -PREMIUMED RPTA MDP 3 | E22: =6792.07-5542.07 -> 1250
C23: (8) LBP | D23: -LPP | E23: =1579.09+30 -> 1609.09
C24: (9) LBP | D24: -LBP Trust Fund Proper | E24: =13100299.14-4122238.07+15415636.1-5412381.29+15862220+5615874.14-15171078.7-4092088.17+4672519.54-165+14808997.18-4485716.44+8850438.88-5675295.86+8907588.89-13749045.72+3134796.33-4622382.41+8404100.29-6720-5223788.81+4906262.2-5306885.4+9423901+800-6595818.57-30000+13037923.57-11361377.98-4958.8+4129799.43-4941365.85-4372.3-36800.09+2643606.66-10041120.25-5301.82+3933853.16-5907264.55+2134584.64-2650921.76+1603047.37-2000-4537984.21+3465788.98-5096720.47-1922+5579782.03-4339072+3712813.19-2693499.26+5770917.83+24228.34-3337331.18+1404510.83-13336+1658.51-3111842.9+1475989.49-1573791.15+3338649.54-5468466.22+3097009.23-4025968.85+14500000 -> 39308574
C25: (10) LBP | D25: -President's Social Fund | E25: =40917.91-7857-243-32500 -> 317.91 | G25: PSF- | H25: PR 20 pcs. Plywood 4x8 | I25: 8100
C26: (11) LBP | D26: -Rural Water Supply | E26: =42649.47-0.4-40500 -> 2149.07 | H26: Cash Adv., >S. Calonzo | I26: 82500
C27: (13) LBP | D27: -BWSA - DPWH | E27: =15647.51-4034.78 -> 11612.73
C28: (12) DBP | D28: -Rural Water Supply | E28: =3067.29 -> 3067.29 | H28: For transfer to TF PROPER | I28: 274885.98
C29: (17) DBP | D29: -Department of Energy | E29: =224470.19 -> 224470.19 | H29: 11/27/08 Adolph Edward Plaza - reimb of TEV | I29: 42693.75
C30: (18) LBP | D30: -Malaria Resource Center | E30: =41048.48+39430-18086.4+4500+3500-15360.41-298.88+13030+6500+3500-2440.2-49.8+1600+1100+1500-3743.6+1000-4510.9+750-90.5+1500+3750-1708+4500-7737.1+250-10187.02+2500-417.88+1750+6500+1000+7000+1950+150-5423.8 -> 78253.99 | H30: 11/27/2008 Joselito S. Aala - reimb of TEV | I30: 10495
C31: (21) DBP | D31: -Malaria Control Project | E31: =1322860.75-28443.5-15506.5-600+45785.41+10876.05+2673.94 -> 1337646.1 | H31: 11/27/2008 Christopher H. Lindo -C/A travel | I31: 49120
C32: (22) LBP | D32: -LGU Support to Malaria for Revolving Fund | E32: =261221.26-40992-34560-1440-24192-1008 -> 159029.26 | I32: 63700 | J32: 12/11/08 | K32: Gov. MA.V.G.PLAZA | M32: travel manila
C33: (23) LBP | D33: -Hospital Revolving Fund | E33: =4981332.63+0.6-1209340.04+766814.05-503404.01+691367.5+738878.15-107861.11-663534.38+717390.81+30643.8+957589.32-518902.43+15270+1607.13+678843.5-849490.65+778966.5-1365899.62+648626.21-886973.92+843319.8-686352.5+1133171.16-2765755.83+833608.49-823050+666554.09-90+0.1-580899.05+1056163.24-583291.34+4372.3+36800.09+654912.49-1195917.63+1575+598574.52-451426.85+647170.55-1423797.21-17035.72+991.07+489714.1-261193.28+812821.7-525356.06+877154.65-870495.89+739516.42-369379.99+818804.85-727862.23+551442.61-0.4-402076.29+728376.5-125195.71+796947.7-162053.98+585193.55-689576.3 -> 5118302.8 | I33: 32500 | J33: 4/07/09 | K33: Sherwin Calonzo - cash advance of 13 packs PVC Plastic
C34: (25) LBP | D34: -DOPMH Revolving Fund | E34: =4092402.61-29640-1405016.22+963423.25-907489.12+922711.86+1658941.6-10872.5-239792.37+1399956.31+1076013.86-1706740.69+1209922.36-1098580.69+1350094.88-2122363.94+1061442.43-2126461.68+1103125.81-45387.45+1540347.9-2054080.03+1248687-1793241.91+983986.49-530035.5+1902921.03-1244111.01+1101808.93-1080903.66+867896.65-931026.88+824262.55-1231533.85+3039.5+955997-335050.85+1073501.4-21323.01+1505553.31-1014419.66+998890.25-393118.05+1178892.38-2079140.08+1286959.27-757139.77+1041088.9-385221.79+1096232.76-1004399.17+1844511.32-2878387.18 -> 6867134.6 | H34: Total | I34: =SUM(I25:I33) -> 563994.73
C35: (26)DBP | D35: -Material Testing | E35: =18542.12-18542.12 -> 0 | F35: 11/12/2009 - close and transfer to GF | H35: Actual Cash Bal. | I35: =E25-I34 -> -563676.82 | J35: 08/08
C36: (28)LBP | D36: -DAR-IFAD-LP | E36: =1008210.21-4718.92-16759.11-58082.1-14605.6-18791.4-9798.66-14413.21-5751.98-4550.08-350+6020.76+4550.08+4550.08-57888 -> 817622.07 | F36: 67,000 IP Balance
C37: (29)LBP | D37: -DAR-IFAD-GOP | E37: =174996.78-112.56-20556+90000-7920-9360-25780-21994.7-6455.65-27029.73-350-6020.76-42374.24-31808.26+13.5-6572.45-6666.4-2613-28484.31-3067.84-795.06-24.59-1650 -> 15374.73
C38: (30)LBP | D38: -Mutual Fund | E38: =459272.31-94500+75321-126000+131049+73498-105000-110160+29767.33+14943-263910+331813-75710+66397-56000+70307-94500+66403-42000+16179-42000+65469+58547-29500-63072+134408-73500+16225-84000+71762-127760+56283-47776+80464-52500+86635-344615.52+188196-108361.48+45188+143496-146801.37+66016.5-10500-61338.66+73586-88000+101532-82000+298391 -> 491643.11
C39: (31)DBP | D39: -PSF-Governor's Guest House | E39: =1156.39 -> 1156.39
C40: (32)DBP | D40: -Blood Screening Fee | E40: =502987.89+29640-222559.07+27400-236.79+39100+240160-2822.12-14973+54600+25500-14977.6+46800-15109.48+52000-15000-17508.93+43100-310027.59+34200-1822.31+190000-326868.15+48400-1863+148750-162294.85+72300-14982.24+63815-15015+47500+57700-9577.87-16259.65-7320.52-991.07+49200-259204.56+260600-204351.83+150700-115745.52+106100-30020.5+38150+39600-567720.5+151500+75900-75000+63150 -> 236600.74
C41: (33)DBP | D41: -MINSSAD | E41: =14803798.86-6861128.87+2545656.29-3006751.37+952089.3+11744516.72-16783233.05-2645608.7+1526866.97-0.4+6693817.8-3556666.12-3063963.75+2241181.97-1768361.05+2844365.78-1215311.07+7870149.5-8799796.61+687849.5+10927288.48-12643272.72+982612.76-575816.71+913075.2-2487538.77+1669444.98+2582821.24-1895838.43+3763454.24-1203620.8+4929193-7003369.09-2854098.99+5206616.49-1180047.58+799410.84-3178116.73+5529592.23-2988096.08-996610.7+4664473.36-1708466.93-19.8+87762.67-3416072.07-897647.3+6619248.78-6571673.94-665528.87+2554699.56-1779097.16 -> 3394232.9
C42: (34)LBP | D42: -SELAP | E42: =3430887.47-282980.06-4533.14+8100000-130471.58-1400412.35-137047.22+2180000-926901.21-2671549.16-1895967.17-1402883.92-226273.73-115493.09+63072-1823297.85+18944.5-442609.37-337486.09+457596.09-1682454.46-60884.11-11850.28-2346.55+120-28134.38-183.91-22544.32-8747.68-5080-2360 -> 628128.43
C43: (35)DBP | D43: DOPMH AFFILIATION | E43: =266284+41700+21820-187500+13235-60+10270+1560+32120+340+19400+2760+18420+26520+23180+6100-55176.8+1020-33587.22+16400+35160-16846.43+7530-953.57+5760 -> 255454.98
...
